g++    -c -o main.o main.cpp
./main.out 20 12 128 0.01 4096 4 0.96 64
<<< PROJECT PART I
<<< -- process set (n=20) with 12 CPU-bound processes
<<< -- seed=128; lambda=0.010000; bound=4096
CPU-bound process A0: arrival time 45ms; 30 CPU bursts:
CPU-bound process A1: arrival time 47ms; 12 CPU bursts:
CPU-bound process A2: arrival time 92ms; 30 CPU bursts:
CPU-bound process A3: arrival time 324ms; 26 CPU bursts:
CPU-bound process A4: arrival time 157ms; 4 CPU bursts:
CPU-bound process A5: arrival time 130ms; 5 CPU bursts:
CPU-bound process A6: arrival time 29ms; 18 CPU bursts:
CPU-bound process A7: arrival time 54ms; 19 CPU bursts:
CPU-bound process A8: arrival time 62ms; 8 CPU bursts:
CPU-bound process A9: arrival time 41ms; 32 CPU bursts:
CPU-bound process B0: arrival time 45ms; 19 CPU bursts:
CPU-bound process B1: arrival time 9ms; 17 CPU bursts:
I/O-bound process B2: arrival time 46ms; 15 CPU bursts:
I/O-bound process B3: arrival time 271ms; 22 CPU bursts:
I/O-bound process B4: arrival time 2ms; 16 CPU bursts:
I/O-bound process B5: arrival time 140ms; 30 CPU bursts:
I/O-bound process B6: arrival time 102ms; 5 CPU bursts:
I/O-bound process B7: arrival time 30ms; 26 CPU bursts:
I/O-bound process B8: arrival time 225ms; 20 CPU bursts:
I/O-bound process B9: arrival time 95ms; 11 CPU bursts:

<<< PROJECT PART II
<<< -- t_cs=4ms; alpha=0.96; t_slice=64ms
Simulating FCFS
time 0ms: Simulator started for FCFS [Q empty]
time 2ms: Process B4 arrived; added to ready queue [Q B4]
time 4ms: Process B4 started using the CPU for 8ms burst [Q empty]
time 9ms: Process B1 arrived; added to ready queue [Q B1]
time 12ms: Process B4 completed a CPU burst; 15 bursts to go [Q B1]
time 12ms: Process B4 switching out of CPU; blocking on I/O until time 984ms [Q B1]
time 16ms: Process B1 started using the CPU for 28ms burst [Q empty]
time 29ms: Process A6 arrived; added to ready queue [Q A6]
time 30ms: Process B7 arrived; added to ready queue [Q A6 B7]
time 41ms: Process A9 arrived; added to ready queue [Q A6 B7 A9]
time 44ms: Process B1 completed a CPU burst; 16 bursts to go [Q A6 B7 A9]
time 44ms: Process B1 switching out of CPU; blocking on I/O until time 266ms [Q A6 B7 A9]
time 45ms: Process A0 arrived; added to ready queue [Q A6 B7 A9 A0]
time 45ms: Process B0 arrived; added to ready queue [Q A6 B7 A9 A0 B0]
time 46ms: Process B2 arrived; added to ready queue [Q A6 B7 A9 A0 B0 B2]
time 47ms: Process A1 arrived; added to ready queue [Q B7 A9 A0 B0 B2 A1]
time 48ms: Process A6 started using the CPU for 280ms burst [Q B7 A9 A0 B0 B2 A1]
time 54ms: Process A7 arrived; added to ready queue [Q B7 A9 A0 B0 B2 A1 A7]
time 62ms: Process A8 arrived; added to ready queue [Q B7 A9 A0 B0 B2 A1 A7 A8]
time 92ms: Process A2 arrived; added to ready queue [Q B7 A9 A0 B0 B2 A1 A7 A8 A2]
time 95ms: Process B9 arrived; added to ready queue [Q B7 A9 A0 B0 B2 A1 A7 A8 A2 B9]
time 102ms: Process B6 arrived; added to ready queue [Q B7 A9 A0 B0 B2 A1 A7 A8 A2 B9 B6]
time 130ms: Process A5 arrived; added to ready queue [Q B7 A9 A0 B0 B2 A1 A7 A8 A2 B9 B6 A5]
time 140ms: Process B5 arrived; added to ready queue [Q B7 A9 A0 B0 B2 A1 A7 A8 A2 B9 B6 A5 B5]
time 157ms: Process A4 arrived; added to ready queue [Q B7 A9 A0 B0 B2 A1 A7 A8 A2 B9 B6 A5 B5 A4]
time 225ms: Process B8 arrived; added to ready queue [Q B7 A9 A0 B0 B2 A1 A7 A8 A2 B9 B6 A5 B5 A4 B8]
time 266ms: Process B1 completed I/O; added to ready queue [Q B7 A9 A0 B0 B2 A1 A7 A8 A2 B9 B6 A5 B5 A4 B8 B1]
time 271ms: Process B3 arrived; added to ready queue [Q B7 A9 A0 B0 B2 A1 A7 A8 A2 B9 B6 A5 B5 A4 B8 B1 B3]
time 324ms: Process A3 arrived; added to ready queue [Q B7 A9 A0 B0 B2 A1 A7 A8 A2 B9 B6 A5 B5 A4 B8 B1 B3 A3]
time 328ms: Process A6 completed a CPU burst; 17 bursts to go [Q B7 A9 A0 B0 B2 A1 A7 A8 A2 B9 B6 A5 B5 A4 B8 B1 B3 A3]
time 328ms: Process A6 switching out of CPU; blocking on I/O until time 404ms [Q B7 A9 A0 B0 B2 A1 A7 A8 A2 B9 B6 A5 B5 A4 B8 B1 B3 A3]
time 332ms: Process B7 started using the CPU for 71ms burst [Q A9 A0 B0 B2 A1 A7 A8 A2 B9 B6 A5 B5 A4 B8 B1 B3 A3]
time 403ms: Process B7 completed a CPU burst; 25 bursts to go [Q A9 A0 B0 B2 A1 A7 A8 A2 B9 B6 A5 B5 A4 B8 B1 B3 A3]
time 403ms: Process B7 switching out of CPU; blocking on I/O until time 3455ms [Q A9 A0 B0 B2 A1 A7 A8 A2 B9 B6 A5 B5 A4 B8 B1 B3 A3]
time 404ms: Process A6 completed I/O; added to ready queue [Q A9 A0 B0 B2 A1 A7 A8 A2 B9 B6 A5 B5 A4 B8 B1 B3 A3 A6]
time 407ms: Process A9 started using the CPU for 360ms burst [Q A0 B0 B2 A1 A7 A8 A2 B9 B6 A5 B5 A4 B8 B1 B3 A3 A6]
time 767ms: Process A9 completed a CPU burst; 31 bursts to go [Q A0 B0 B2 A1 A7 A8 A2 B9 B6 A5 B5 A4 B8 B1 B3 A3 A6]
time 767ms: Process A9 switching out of CPU; blocking on I/O until time 811ms [Q A0 B0 B2 A1 A7 A8 A2 B9 B6 A5 B5 A4 B8 B1 B3 A3 A6]
time 771ms: Process A0 started using the CPU for 196ms burst [Q B0 B2 A1 A7 A8 A2 B9 B6 A5 B5 A4 B8 B1 B3 A3 A6]
time 811ms: Process A9 completed I/O; added to ready queue [Q B0 B2 A1 A7 A8 A2 B9 B6 A5 B5 A4 B8 B1 B3 A3 A6 A9]
time 967ms: Process A0 completed a CPU burst; 29 bursts to go [Q B0 B2 A1 A7 A8 A2 B9 B6 A5 B5 A4 B8 B1 B3 A3 A6 A9]
time 967ms: Process A0 switching out of CPU; blocking on I/O until time 1050ms [Q B0 B2 A1 A7 A8 A2 B9 B6 A5 B5 A4 B8 B1 B3 A3 A6 A9]
time 971ms: Process B0 started using the CPU for 216ms burst [Q B2 A1 A7 A8 A2 B9 B6 A5 B5 A4 B8 B1 B3 A3 A6 A9]
time 984ms: Process B4 completed I/O; added to ready queue [Q B2 A1 A7 A8 A2 B9 B6 A5 B5 A4 B8 B1 B3 A3 A6 A9 B4]
time 1050ms: Process A0 completed I/O; added to ready queue [Q B2 A1 A7 A8 A2 B9 B6 A5 B5 A4 B8 B1 B3 A3 A6 A9 B4 A0]
time 1187ms: Process B0 completed a CPU burst; 18 bursts to go [Q B2 A1 A7 A8 A2 B9 B6 A5 B5 A4 B8 B1 B3 A3 A6 A9 B4 A0]
time 1187ms: Process B0 switching out of CPU; blocking on I/O until time 1340ms [Q B2 A1 A7 A8 A2 B9 B6 A5 B5 A4 B8 B1 B3 A3 A6 A9 B4 A0]
time 1191ms: Process B2 started using the CPU for 122ms burst [Q A1 A7 A8 A2 B9 B6 A5 B5 A4 B8 B1 B3 A3 A6 A9 B4 A0]
time 1313ms: Process B2 completed a CPU burst; 14 bursts to go [Q A1 A7 A8 A2 B9 B6 A5 B5 A4 B8 B1 B3 A3 A6 A9 B4 A0]
time 1313ms: Process B2 switching out of CPU; blocking on I/O until time 1837ms [Q A1 A7 A8 A2 B9 B6 A5 B5 A4 B8 B1 B3 A3 A6 A9 B4 A0]
time 1317ms: Process A1 started using the CPU for 632ms burst [Q A7 A8 A2 B9 B6 A5 B5 A4 B8 B1 B3 A3 A6 A9 B4 A0]
time 1340ms: Process B0 completed I/O; added to ready queue [Q A7 A8 A2 B9 B6 A5 B5 A4 B8 B1 B3 A3 A6 A9 B4 A0 B0]
time 1837ms: Process B2 completed I/O; added to ready queue [Q A7 A8 A2 B9 B6 A5 B5 A4 B8 B1 B3 A3 A6 A9 B4 A0 B0 B2]
time 1949ms: Process A1 completed a CPU burst; 11 bursts to go [Q A7 A8 A2 B9 B6 A5 B5 A4 B8 B1 B3 A3 A6 A9 B4 A0 B0 B2]
time 1949ms: Process A1 switching out of CPU; blocking on I/O until time 1991ms [Q A7 A8 A2 B9 B6 A5 B5 A4 B8 B1 B3 A3 A6 A9 B4 A0 B0 B2]
time 1953ms: Process A7 started using the CPU for 84ms burst [Q A8 A2 B9 B6 A5 B5 A4 B8 B1 B3 A3 A6 A9 B4 A0 B0 B2]
time 1991ms: Process A1 completed I/O; added to ready queue [Q A8 A2 B9 B6 A5 B5 A4 B8 B1 B3 A3 A6 A9 B4 A0 B0 B2 A1]
time 2037ms: Process A7 completed a CPU burst; 18 bursts to go [Q A8 A2 B9 B6 A5 B5 A4 B8 B1 B3 A3 A6 A9 B4 A0 B0 B2 A1]
time 2037ms: Process A7 switching out of CPU; blocking on I/O until time 2090ms [Q A8 A2 B9 B6 A5 B5 A4 B8 B1 B3 A3 A6 A9 B4 A0 B0 B2 A1]
time 2041ms: Process A8 started using the CPU for 420ms burst [Q A2 B9 B6 A5 B5 A4 B8 B1 B3 A3 A6 A9 B4 A0 B0 B2 A1]
time 2090ms: Process A7 completed I/O; added to ready queue [Q A2 B9 B6 A5 B5 A4 B8 B1 B3 A3 A6 A9 B4 A0 B0 B2 A1 A7]
time 2461ms: Process A8 completed a CPU burst; 7 bursts to go [Q A2 B9 B6 A5 B5 A4 B8 B1 B3 A3 A6 A9 B4 A0 B0 B2 A1 A7]
time 2461ms: Process A8 switching out of CPU; blocking on I/O until time 2519ms [Q A2 B9 B6 A5 B5 A4 B8 B1 B3 A3 A6 A9 B4 A0 B0 B2 A1 A7]
time 2465ms: Process A2 started using the CPU for 28ms burst [Q B9 B6 A5 B5 A4 B8 B1 B3 A3 A6 A9 B4 A0 B0 B2 A1 A7]
time 2493ms: Process A2 completed a CPU burst; 29 bursts to go [Q B9 B6 A5 B5 A4 B8 B1 B3 A3 A6 A9 B4 A0 B0 B2 A1 A7]
time 2493ms: Process A2 switching out of CPU; blocking on I/O until time 2510ms [Q B9 B6 A5 B5 A4 B8 B1 B3 A3 A6 A9 B4 A0 B0 B2 A1 A7]
time 2497ms: Process B9 started using the CPU for 22ms burst [Q B6 A5 B5 A4 B8 B1 B3 A3 A6 A9 B4 A0 B0 B2 A1 A7]
time 2510ms: Process A2 completed I/O; added to ready queue [Q B6 A5 B5 A4 B8 B1 B3 A3 A6 A9 B4 A0 B0 B2 A1 A7 A2]
time 2519ms: Process B9 completed a CPU burst; 10 bursts to go [Q B6 A5 B5 A4 B8 B1 B3 A3 A6 A9 B4 A0 B0 B2 A1 A7 A2]
time 2519ms: Process B9 switching out of CPU; blocking on I/O until time 3131ms [Q B6 A5 B5 A4 B8 B1 B3 A3 A6 A9 B4 A0 B0 B2 A1 A7 A2]
time 2519ms: Process A8 completed I/O; added to ready queue [Q B6 A5 B5 A4 B8 B1 B3 A3 A6 A9 B4 A0 B0 B2 A1 A7 A2 A8]
time 2523ms: Process B6 started using the CPU for 113ms burst [Q A5 B5 A4 B8 B1 B3 A3 A6 A9 B4 A0 B0 B2 A1 A7 A2 A8]
time 2636ms: Process B6 completed a CPU burst; 4 bursts to go [Q A5 B5 A4 B8 B1 B3 A3 A6 A9 B4 A0 B0 B2 A1 A7 A2 A8]
time 2636ms: Process B6 switching out of CPU; blocking on I/O until time 5864ms [Q A5 B5 A4 B8 B1 B3 A3 A6 A9 B4 A0 B0 B2 A1 A7 A2 A8]
time 2640ms: Process A5 started using the CPU for 196ms burst [Q B5 A4 B8 B1 B3 A3 A6 A9 B4 A0 B0 B2 A1 A7 A2 A8]
time 2836ms: Process A5 completed a CPU burst; 4 bursts to go [Q B5 A4 B8 B1 B3 A3 A6 A9 B4 A0 B0 B2 A1 A7 A2 A8]
time 2836ms: Process A5 switching out of CPU; blocking on I/O until time 2857ms [Q B5 A4 B8 B1 B3 A3 A6 A9 B4 A0 B0 B2 A1 A7 A2 A8]
time 2840ms: Process B5 started using the CPU for 20ms burst [Q A4 B8 B1 B3 A3 A6 A9 B4 A0 B0 B2 A1 A7 A2 A8]
time 2857ms: Process A5 completed I/O; added to ready queue [Q A4 B8 B1 B3 A3 A6 A9 B4 A0 B0 B2 A1 A7 A2 A8 A5]
time 2860ms: Process B5 completed a CPU burst; 29 bursts to go [Q A4 B8 B1 B3 A3 A6 A9 B4 A0 B0 B2 A1 A7 A2 A8 A5]
time 2860ms: Process B5 switching out of CPU; blocking on I/O until time 3112ms [Q A4 B8 B1 B3 A3 A6 A9 B4 A0 B0 B2 A1 A7 A2 A8 A5]
time 2864ms: Process A4 started using the CPU for 300ms burst [Q B8 B1 B3 A3 A6 A9 B4 A0 B0 B2 A1 A7 A2 A8 A5]
time 3112ms: Process B5 completed I/O; added to ready queue [Q B8 B1 B3 A3 A6 A9 B4 A0 B0 B2 A1 A7 A2 A8 A5 B5]
time 3131ms: Process B9 completed I/O; added to ready queue [Q B8 B1 B3 A3 A6 A9 B4 A0 B0 B2 A1 A7 A2 A8 A5 B5 B9]
time 3164ms: Process A4 completed a CPU burst; 3 bursts to go [Q B8 B1 B3 A3 A6 A9 B4 A0 B0 B2 A1 A7 A2 A8 A5 B5 B9]
time 3164ms: Process A4 switching out of CPU; blocking on I/O until time 3257ms [Q B8 B1 B3 A3 A6 A9 B4 A0 B0 B2 A1 A7 A2 A8 A5 B5 B9]
time 3168ms: Process B8 started using the CPU for 308ms burst [Q B1 B3 A3 A6 A9 B4 A0 B0 B2 A1 A7 A2 A8 A5 B5 B9]
time 3257ms: Process A4 completed I/O; added to ready queue [Q B1 B3 A3 A6 A9 B4 A0 B0 B2 A1 A7 A2 A8 A5 B5 B9 A4]
time 3455ms: Process B7 completed I/O; added to ready queue [Q B1 B3 A3 A6 A9 B4 A0 B0 B2 A1 A7 A2 A8 A5 B5 B9 A4 B7]
time 3476ms: Process B8 completed a CPU burst; 19 bursts to go [Q B1 B3 A3 A6 A9 B4 A0 B0 B2 A1 A7 A2 A8 A5 B5 B9 A4 B7]
time 3476ms: Process B8 switching out of CPU; blocking on I/O until time 5760ms [Q B1 B3 A3 A6 A9 B4 A0 B0 B2 A1 A7 A2 A8 A5 B5 B9 A4 B7]
time 3480ms: Process B1 started using the CPU for 3004ms burst [Q B3 A3 A6 A9 B4 A0 B0 B2 A1 A7 A2 A8 A5 B5 B9 A4 B7]
time 5760ms: Process B8 completed I/O; added to ready queue [Q B3 A3 A6 A9 B4 A0 B0 B2 A1 A7 A2 A8 A5 B5 B9 A4 B7 B8]
time 5864ms: Process B6 completed I/O; added to ready queue [Q B3 A3 A6 A9 B4 A0 B0 B2 A1 A7 A2 A8 A5 B5 B9 A4 B7 B8 B6]
time 6484ms: Process B1 completed a CPU burst; 15 bursts to go [Q B3 A3 A6 A9 B4 A0 B0 B2 A1 A7 A2 A8 A5 B5 B9 A4 B7 B8 B6]
time 6484ms: Process B1 switching out of CPU; blocking on I/O until time 6627ms [Q B3 A3 A6 A9 B4 A0 B0 B2 A1 A7 A2 A8 A5 B5 B9 A4 B7 B8 B6]
time 6488ms: Process B3 started using the CPU for 51ms burst [Q A3 A6 A9 B4 A0 B0 B2 A1 A7 A2 A8 A5 B5 B9 A4 B7 B8 B6]
time 6539ms: Process B3 completed a CPU burst; 21 bursts to go [Q A3 A6 A9 B4 A0 B0 B2 A1 A7 A2 A8 A5 B5 B9 A4 B7 B8 B6]
time 6539ms: Process B3 switching out of CPU; blocking on I/O until time 8879ms [Q A3 A6 A9 B4 A0 B0 B2 A1 A7 A2 A8 A5 B5 B9 A4 B7 B8 B6]
time 6543ms: Process A3 started using the CPU for 96ms burst [Q A6 A9 B4 A0 B0 B2 A1 A7 A2 A8 A5 B5 B9 A4 B7 B8 B6]
time 6627ms: Process B1 completed I/O; added to ready queue [Q A6 A9 B4 A0 B0 B2 A1 A7 A2 A8 A5 B5 B9 A4 B7 B8 B6 B1]
time 6639ms: Process A3 completed a CPU burst; 25 bursts to go [Q A6 A9 B4 A0 B0 B2 A1 A7 A2 A8 A5 B5 B9 A4 B7 B8 B6 B1]
time 6639ms: Process A3 switching out of CPU; blocking on I/O until time 7013ms [Q A6 A9 B4 A0 B0 B2 A1 A7 A2 A8 A5 B5 B9 A4 B7 B8 B6 B1]
time 6643ms: Process A6 started using the CPU for 100ms burst [Q A9 B4 A0 B0 B2 A1 A7 A2 A8 A5 B5 B9 A4 B7 B8 B6 B1]
time 6743ms: Process A6 completed a CPU burst; 16 bursts to go [Q A9 B4 A0 B0 B2 A1 A7 A2 A8 A5 B5 B9 A4 B7 B8 B6 B1]
time 6743ms: Process A6 switching out of CPU; blocking on I/O until time 6762ms [Q A9 B4 A0 B0 B2 A1 A7 A2 A8 A5 B5 B9 A4 B7 B8 B6 B1]
time 6747ms: Process A9 started using the CPU for 28ms burst [Q B4 A0 B0 B2 A1 A7 A2 A8 A5 B5 B9 A4 B7 B8 B6 B1]
time 6762ms: Process A6 completed I/O; added to ready queue [Q B4 A0 B0 B2 A1 A7 A2 A8 A5 B5 B9 A4 B7 B8 B6 B1 A6]
time 6775ms: Process A9 completed a CPU burst; 30 bursts to go [Q B4 A0 B0 B2 A1 A7 A2 A8 A5 B5 B9 A4 B7 B8 B6 B1 A6]
time 6775ms: Process A9 switching out of CPU; blocking on I/O until time 6807ms [Q B4 A0 B0 B2 A1 A7 A2 A8 A5 B5 B9 A4 B7 B8 B6 B1 A6]
time 6779ms: Process B4 started using the CPU for 3ms burst [Q A0 B0 B2 A1 A7 A2 A8 A5 B5 B9 A4 B7 B8 B6 B1 A6]
time 6782ms: Process B4 completed a CPU burst; 14 bursts to go [Q A0 B0 B2 A1 A7 A2 A8 A5 B5 B9 A4 B7 B8 B6 B1 A6]
time 6782ms: Process B4 switching out of CPU; blocking on I/O until time 7882ms [Q A0 B0 B2 A1 A7 A2 A8 A5 B5 B9 A4 B7 B8 B6 B1 A6]
time 6786ms: Process A0 started using the CPU for 1096ms burst [Q B0 B2 A1 A7 A2 A8 A5 B5 B9 A4 B7 B8 B6 B1 A6]
time 6807ms: Process A9 completed I/O; added to ready queue [Q B0 B2 A1 A7 A2 A8 A5 B5 B9 A4 B7 B8 B6 B1 A6 A9]
time 7013ms: Process A3 completed I/O; added to ready queue [Q B0 B2 A1 A7 A2 A8 A5 B5 B9 A4 B7 B8 B6 B1 A6 A9 A3]
time 7882ms: Process A0 completed a CPU burst; 28 bursts to go [Q B0 B2 A1 A7 A2 A8 A5 B5 B9 A4 B7 B8 B6 B1 A6 A9 A3]
time 7882ms: Process A0 switching out of CPU; blocking on I/O until time 7971ms [Q B0 B2 A1 A7 A2 A8 A5 B5 B9 A4 B7 B8 B6 B1 A6 A9 A3]
time 7882ms: Process B4 completed I/O; added to ready queue [Q B0 B2 A1 A7 A2 A8 A5 B5 B9 A4 B7 B8 B6 B1 A6 A9 A3 B4]
time 7886ms: Process B0 started using the CPU for 1264ms burst [Q B2 A1 A7 A2 A8 A5 B5 B9 A4 B7 B8 B6 B1 A6 A9 A3 B4]
time 7971ms: Process A0 completed I/O; added to ready queue [Q B2 A1 A7 A2 A8 A5 B5 B9 A4 B7 B8 B6 B1 A6 A9 A3 B4 A0]
time 8879ms: Process B3 completed I/O; added to ready queue [Q B2 A1 A7 A2 A8 A5 B5 B9 A4 B7 B8 B6 B1 A6 A9 A3 B4 A0 B3]
time 9150ms: Process B0 completed a CPU burst; 17 bursts to go [Q B2 A1 A7 A2 A8 A5 B5 B9 A4 B7 B8 B6 B1 A6 A9 A3 B4 A0 B3]
time 9150ms: Process B0 switching out of CPU; blocking on I/O until time 9163ms [Q B2 A1 A7 A2 A8 A5 B5 B9 A4 B7 B8 B6 B1 A6 A9 A3 B4 A0 B3]
time 9154ms: Process B2 started using the CPU for 183ms burst [Q A1 A7 A2 A8 A5 B5 B9 A4 B7 B8 B6 B1 A6 A9 A3 B4 A0 B3]
time 9163ms: Process B0 completed I/O; added to ready queue [Q A1 A7 A2 A8 A5 B5 B9 A4 B7 B8 B6 B1 A6 A9 A3 B4 A0 B3 B0]
time 9337ms: Process B2 completed a CPU burst; 13 bursts to go [Q A1 A7 A2 A8 A5 B5 B9 A4 B7 B8 B6 B1 A6 A9 A3 B4 A0 B3 B0]
time 9337ms: Process B2 switching out of CPU; blocking on I/O until time 9653ms [Q A1 A7 A2 A8 A5 B5 B9 A4 B7 B8 B6 B1 A6 A9 A3 B4 A0 B3 B0]
time 9341ms: Process A1 started using the CPU for 200ms burst [Q A7 A2 A8 A5 B5 B9 A4 B7 B8 B6 B1 A6 A9 A3 B4 A0 B3 B0]
time 9541ms: Process A1 completed a CPU burst; 10 bursts to go [Q A7 A2 A8 A5 B5 B9 A4 B7 B8 B6 B1 A6 A9 A3 B4 A0 B3 B0]
time 9541ms: Process A1 switching out of CPU; blocking on I/O until time 9577ms [Q A7 A2 A8 A5 B5 B9 A4 B7 B8 B6 B1 A6 A9 A3 B4 A0 B3 B0]
time 9545ms: Process A7 started using the CPU for 768ms burst [Q A2 A8 A5 B5 B9 A4 B7 B8 B6 B1 A6 A9 A3 B4 A0 B3 B0]
time 9577ms: Process A1 completed I/O; added to ready queue [Q A2 A8 A5 B5 B9 A4 B7 B8 B6 B1 A6 A9 A3 B4 A0 B3 B0 A1]
time 9653ms: Process B2 completed I/O; added to ready queue [Q A2 A8 A5 B5 B9 A4 B7 B8 B6 B1 A6 A9 A3 B4 A0 B3 B0 A1 B2]
time 24234ms: Process A4 terminated [Q B1 B8 A9 A6 A3 B4 B7 B6 A0 B0 A1 B3 B2 A7 A8 A5 A2 B9]
time 28341ms: Process A5 terminated [Q A2 B9 B1 B5 A9 A6 B4 A3 B6 A0 B0 A1 B2 B3 A7 B8 A8]
time 29744ms: Process B6 terminated [Q A0 B0 A1 B2 B3 A7 B8 A8 A2 B5 B1 B9 B7 A9 A6]
time 41688ms: Process A8 terminated [Q A2 B8 B5 B9 A9 A6 B1 A3 B0 A0 A1 B3 B2 A7]
time 60712ms: Process B9 terminated [Q B2 A1 A7 B7 A2 B5 B8 A9 A6 A3 B0 B1 A0]
time 61077ms: Process A1 terminated [Q A7 B7 A2 B5 B8 A9 A6 A3 B0 B1 A0]
time 72901ms: Process B2 terminated [Q A2 B8 A6 A9 B4 B5 B0 B1 A3 B3 A7 A0]
time 74012ms: Process B1 terminated [Q A3 B3 A7 A0 A2 A9 A6 B4 B7 B8 B0]
time 77473ms: Process A6 terminated [Q B4 B7 B8 B0 B5 A3 A7 A0 A2 B3 A9]
time 77722ms: Process B4 terminated [Q B7 B8 B0 B5 A3 A7 A0 A2 B3 A9]
time 81346ms: Process B0 terminated [Q A7 A0 A2 A9 B5 B3 A3 B8]
time 81389ms: Process A7 terminated [Q A0 A2 A9 B5 B3 A3 B8]
time 94114ms: Process B8 terminated [Q A2 B7 B3 A9 A3 B5]
time 98372ms: Process A3 terminated [Q A2 A0 A9]
time 104808ms: Process A2 terminated [Q B3 A0 B5 A9 B7]
time 105584ms: Process A0 terminated [Q B5 A9 B7 B3]
time 106768ms: Process A9 terminated [Q B7]
time 107518ms: Process B7 terminated [Q empty]
time 108831ms: Process B3 terminated [Q empty]
time 109685ms: Process B5 terminated [Q empty]
time 109687ms: Simulator ended for FCFS [Q empty]
FCFS simulation completed

Simulating SJF
time 0ms: Simulator started for SJF [Q empty]
time 2ms: Process B4 (tau 100ms) arrived; added to ready queue [Q B4]
time 4ms: Process B4 (tau 100ms) started using the CPU for 8ms burst [Q empty]
time 9ms: Process B1 (tau 100ms) arrived; added to ready queue [Q B1]
time 12ms: Process B4 (tau 100ms) completed a CPU burst; 15 bursts to go [Q B1]
time 12ms: Recalculated tau for process B4: old tau 100ms ==> new tau 12ms [Q B1]
time 12ms: Process B4 switching out of CPU; blocking on I/O until time 984ms [Q B1]
time 16ms: Process B1 (tau 100ms) started using the CPU for 28ms burst [Q empty]
time 29ms: Process A6 (tau 100ms) arrived; added to ready queue [Q A6]
time 30ms: Process B7 (tau 100ms) arrived; added to ready queue [Q A6 B7]
time 41ms: Process A9 (tau 100ms) arrived; added to ready queue [Q A6 A9 B7]
time 44ms: Process B1 (tau 100ms) completed a CPU burst; 16 bursts to go [Q A6 A9 B7]
time 44ms: Recalculated tau for process B1: old tau 100ms ==> new tau 31ms [Q A6 A9 B7]
time 44ms: Process B1 switching out of CPU; blocking on I/O until time 266ms [Q A6 A9 B7]
time 45ms: Process A0 (tau 100ms) arrived; added to ready queue [Q A0 A6 A9 B7]
time 45ms: Process B0 (tau 100ms) arrived; added to ready queue [Q A0 A6 A9 B0 B7]
time 46ms: Process B2 (tau 100ms) arrived; added to ready queue [Q A0 A6 A9 B0 B2 B7]
time 47ms: Process A1 (tau 100ms) arrived; added to ready queue [Q A1 A6 A9 B0 B2 B7]
time 48ms: Process A0 (tau 100ms) started using the CPU for 196ms burst [Q A1 A6 A9 B0 B2 B7]
time 54ms: Process A7 (tau 100ms) arrived; added to ready queue [Q A1 A6 A7 A9 B0 B2 B7]
time 62ms: Process A8 (tau 100ms) arrived; added to ready queue [Q A1 A6 A7 A8 A9 B0 B2 B7]
time 92ms: Process A2 (tau 100ms) arrived; added to ready queue [Q A1 A2 A6 A7 A8 A9 B0 B2 B7]
time 95ms: Process B9 (tau 100ms) arrived; added to ready queue [Q A1 A2 A6 A7 A8 A9 B0 B2 B7 B9]
time 102ms: Process B6 (tau 100ms) arrived; added to ready queue [Q A1 A2 A6 A7 A8 A9 B0 B2 B6 B7 B9]
time 130ms: Process A5 (tau 100ms) arrived; added to ready queue [Q A1 A2 A5 A6 A7 A8 A9 B0 B2 B6 B7 B9]
time 140ms: Process B5 (tau 100ms) arrived; added to ready queue [Q A1 A2 A5 A6 A7 A8 A9 B0 B2 B5 B6 B7 B9]
time 157ms: Process A4 (tau 100ms) arrived; added to ready queue [Q A1 A2 A4 A5 A6 A7 A8 A9 B0 B2 B5 B6 B7 B9]
time 225ms: Process B8 (tau 100ms) arrived; added to ready queue [Q A1 A2 A4 A5 A6 A7 A8 A9 B0 B2 B5 B6 B7 B8 B9]
time 244ms: Process A0 (tau 100ms) completed a CPU burst; 29 bursts to go [Q A1 A2 A4 A5 A6 A7 A8 A9 B0 B2 B5 B6 B7 B8 B9]
time 244ms: Recalculated tau for process A0: old tau 100ms ==> new tau 193ms [Q A1 A2 A4 A5 A6 A7 A8 A9 B0 B2 B5 B6 B7 B8 B9]
time 244ms: Process A0 switching out of CPU; blocking on I/O until time 327ms [Q A1 A2 A4 A5 A6 A7 A8 A9 B0 B2 B5 B6 B7 B8 B9]
time 248ms: Process A1 (tau 100ms) started using the CPU for 632ms burst [Q A2 A4 A5 A6 A7 A8 A9 B0 B2 B5 B6 B7 B8 B9]
time 266ms: Process B1 (tau 31ms) completed I/O; added to ready queue [Q B1 A2 A4 A5 A6 A7 A8 A9 B0 B2 B5 B6 B7 B8 B9]
time 271ms: Process B3 (tau 100ms) arrived; added to ready queue [Q B1 A2 A4 A5 A6 A7 A8 A9 B0 B2 B3 B5 B6 B7 B8 B9]
time 324ms: Process A3 (tau 100ms) arrived; added to ready queue [Q B1 A2 A3 A4 A5 A6 A7 A8 A9 B0 B2 B3 B5 B6 B7 B8 B9]
time 327ms: Process A0 (tau 193ms) completed I/O; added to ready queue [Q B1 A2 A3 A4 A5 A6 A7 A8 A9 B0 B2 B3 B5 B6 B7 B8 B9 A0]
time 880ms: Process A1 (tau 100ms) completed a CPU burst; 11 bursts to go [Q B1 A2 A3 A4 A5 A6 A7 A8 A9 B0 B2 B3 B5 B6 B7 B8 B9 A0]
time 880ms: Recalculated tau for process A1: old tau 100ms ==> new tau 611ms [Q B1 A2 A3 A4 A5 A6 A7 A8 A9 B0 B2 B3 B5 B6 B7 B8 B9 A0]
time 880ms: Process A1 switching out of CPU; blocking on I/O until time 922ms [Q B1 A2 A3 A4 A5 A6 A7 A8 A9 B0 B2 B3 B5 B6 B7 B8 B9 A0]
time 884ms: Process B1 (tau 31ms) started using the CPU for 3004ms burst [Q A2 A3 A4 A5 A6 A7 A8 A9 B0 B2 B3 B5 B6 B7 B8 B9 A0]
time 922ms: Process A1 (tau 611ms) completed I/O; added to ready queue [Q A2 A3 A4 A5 A6 A7 A8 A9 B0 B2 B3 B5 B6 B7 B8 B9 A0 A1]
time 984ms: Process B4 (tau 12ms) completed I/O; added to ready queue [Q B4 A2 A3 A4 A5 A6 A7 A8 A9 B0 B2 B3 B5 B6 B7 B8 B9 A0 A1]
time 3888ms: Process B1 (tau 31ms) completed a CPU burst; 15 bursts to go [Q B4 A2 A3 A4 A5 A6 A7 A8 A9 B0 B2 B3 B5 B6 B7 B8 B9 A0 A1]
time 3888ms: Recalculated tau for process B1: old tau 31ms ==> new tau 2886ms [Q B4 A2 A3 A4 A5 A6 A7 A8 A9 B0 B2 B3 B5 B6 B7 B8 B9 A0 A1]
time 3888ms: Process B1 switching out of CPU; blocking on I/O until time 4031ms [Q B4 A2 A3 A4 A5 A6 A7 A8 A9 B0 B2 B3 B5 B6 B7 B8 B9 A0 A1]
time 3892ms: Process B4 (tau 12ms) started using the CPU for 3ms burst [Q A2 A3 A4 A5 A6 A7 A8 A9 B0 B2 B3 B5 B6 B7 B8 B9 A0 A1]
time 3895ms: Process B4 (tau 12ms) completed a CPU burst; 14 bursts to go [Q A2 A3 A4 A5 A6 A7 A8 A9 B0 B2 B3 B5 B6 B7 B8 B9 A0 A1]
time 3895ms: Recalculated tau for process B4: old tau 12ms ==> new tau 4ms [Q A2 A3 A4 A5 A6 A7 A8 A9 B0 B2 B3 B5 B6 B7 B8 B9 A0 A1]
time 3895ms: Process B4 switching out of CPU; blocking on I/O until time 4995ms [Q A2 A3 A4 A5 A6 A7 A8 A9 B0 B2 B3 B5 B6 B7 B8 B9 A0 A1]
time 3899ms: Process A2 (tau 100ms) started using the CPU for 28ms burst [Q A3 A4 A5 A6 A7 A8 A9 B0 B2 B3 B5 B6 B7 B8 B9 A0 A1]
time 3927ms: Process A2 (tau 100ms) completed a CPU burst; 29 bursts to go [Q A3 A4 A5 A6 A7 A8 A9 B0 B2 B3 B5 B6 B7 B8 B9 A0 A1]
time 3927ms: Recalculated tau for process A2: old tau 100ms ==> new tau 31ms [Q A3 A4 A5 A6 A7 A8 A9 B0 B2 B3 B5 B6 B7 B8 B9 A0 A1]
time 3927ms: Process A2 switching out of CPU; blocking on I/O until time 3944ms [Q A3 A4 A5 A6 A7 A8 A9 B0 B2 B3 B5 B6 B7 B8 B9 A0 A1]
time 3931ms: Process A3 (tau 100ms) started using the CPU for 96ms burst [Q A4 A5 A6 A7 A8 A9 B0 B2 B3 B5 B6 B7 B8 B9 A0 A1]
time 3944ms: Process A2 (tau 31ms) completed I/O; added to ready queue [Q A2 A4 A5 A6 A7 A8 A9 B0 B2 B3 B5 B6 B7 B8 B9 A0 A1]
time 4027ms: Process A3 (tau 100ms) completed a CPU burst; 25 bursts to go [Q A2 A4 A5 A6 A7 A8 A9 B0 B2 B3 B5 B6 B7 B8 B9 A0 A1]
time 4027ms: Recalculated tau for process A3: old tau 100ms ==> new tau 97ms [Q A2 A4 A5 A6 A7 A8 A9 B0 B2 B3 B5 B6 B7 B8 B9 A0 A1]
time 4027ms: Process A3 switching out of CPU; blocking on I/O until time 4401ms [Q A2 A4 A5 A6 A7 A8 A9 B0 B2 B3 B5 B6 B7 B8 B9 A0 A1]
time 4031ms: Process B1 (tau 2886ms) completed I/O; added to ready queue [Q A4 A5 A6 A7 A8 A9 B0 B2 B3 B5 B6 B7 B8 B9 A0 A1 B1]
time 4031ms: Process A2 (tau 31ms) started using the CPU for 444ms burst [Q A4 A5 A6 A7 A8 A9 B0 B2 B3 B5 B6 B7 B8 B9 A0 A1 B1]
time 4401ms: Process A3 (tau 97ms) completed I/O; added to ready queue [Q A3 A4 A5 A6 A7 A8 A9 B0 B2 B3 B5 B6 B7 B8 B9 A0 A1 B1]
time 4475ms: Process A2 (tau 31ms) completed a CPU burst; 28 bursts to go [Q A3 A4 A5 A6 A7 A8 A9 B0 B2 B3 B5 B6 B7 B8 B9 A0 A1 B1]
time 4475ms: Recalculated tau for process A2: old tau 31ms ==> new tau 428ms [Q A3 A4 A5 A6 A7 A8 A9 B0 B2 B3 B5 B6 B7 B8 B9 A0 A1 B1]
time 4475ms: Process A2 switching out of CPU; blocking on I/O until time 4938ms [Q A3 A4 A5 A6 A7 A8 A9 B0 B2 B3 B5 B6 B7 B8 B9 A0 A1 B1]
time 4479ms: Process A3 (tau 97ms) started using the CPU for 308ms burst [Q A4 A5 A6 A7 A8 A9 B0 B2 B3 B5 B6 B7 B8 B9 A0 A1 B1]
time 4787ms: Process A3 (tau 97ms) completed a CPU burst; 24 bursts to go [Q A4 A5 A6 A7 A8 A9 B0 B2 B3 B5 B6 B7 B8 B9 A0 A1 B1]
time 4787ms: Recalculated tau for process A3: old tau 97ms ==> new tau 300ms [Q A4 A5 A6 A7 A8 A9 B0 B2 B3 B5 B6 B7 B8 B9 A0 A1 B1]
time 4787ms: Process A3 switching out of CPU; blocking on I/O until time 4879ms [Q A4 A5 A6 A7 A8 A9 B0 B2 B3 B5 B6 B7 B8 B9 A0 A1 B1]
time 4791ms: Process A4 (tau 100ms) started using the CPU for 300ms burst [Q A5 A6 A7 A8 A9 B0 B2 B3 B5 B6 B7 B8 B9 A0 A1 B1]
time 4879ms: Process A3 (tau 300ms) completed I/O; added to ready queue [Q A5 A6 A7 A8 A9 B0 B2 B3 B5 B6 B7 B8 B9 A0 A3 A1 B1]
time 4938ms: Process A2 (tau 428ms) completed I/O; added to ready queue [Q A5 A6 A7 A8 A9 B0 B2 B3 B5 B6 B7 B8 B9 A0 A3 A2 A1 B1]
time 4995ms: Process B4 (tau 4ms) completed I/O; added to ready queue [Q B4 A5 A6 A7 A8 A9 B0 B2 B3 B5 B6 B7 B8 B9 A0 A3 A2 A1 B1]
time 5091ms: Process A4 (tau 100ms) completed a CPU burst; 3 bursts to go [Q B4 A5 A6 A7 A8 A9 B0 B2 B3 B5 B6 B7 B8 B9 A0 A3 A2 A1 B1]
time 5091ms: Recalculated tau for process A4: old tau 100ms ==> new tau 292ms [Q B4 A5 A6 A7 A8 A9 B0 B2 B3 B5 B6 B7 B8 B9 A0 A3 A2 A1 B1]
time 5091ms: Process A4 switching out of CPU; blocking on I/O until time 5184ms [Q B4 A5 A6 A7 A8 A9 B0 B2 B3 B5 B6 B7 B8 B9 A0 A3 A2 A1 B1]
time 5095ms: Process B4 (tau 4ms) started using the CPU for 285ms burst [Q A5 A6 A7 A8 A9 B0 B2 B3 B5 B6 B7 B8 B9 A0 A3 A2 A1 B1]
time 5184ms: Process A4 (tau 292ms) completed I/O; added to ready queue [Q A5 A6 A7 A8 A9 B0 B2 B3 B5 B6 B7 B8 B9 A0 A4 A3 A2 A1 B1]
time 5380ms: Process B4 (tau 4ms) completed a CPU burst; 13 bursts to go [Q A5 A6 A7 A8 A9 B0 B2 B3 B5 B6 B7 B8 B9 A0 A4 A3 A2 A1 B1]
time 5380ms: Recalculated tau for process B4: old tau 4ms ==> new tau 274ms [Q A5 A6 A7 A8 A9 B0 B2 B3 B5 B6 B7 B8 B9 A0 A4 A3 A2 A1 B1]
time 5380ms: Process B4 switching out of CPU; blocking on I/O until time 5608ms [Q A5 A6 A7 A8 A9 B0 B2 B3 B5 B6 B7 B8 B9 A0 A4 A3 A2 A1 B1]
time 5384ms: Process A5 (tau 100ms) started using the CPU for 196ms burst [Q A6 A7 A8 A9 B0 B2 B3 B5 B6 B7 B8 B9 A0 A4 A3 A2 A1 B1]
time 5580ms: Process A5 (tau 100ms) completed a CPU burst; 4 bursts to go [Q A6 A7 A8 A9 B0 B2 B3 B5 B6 B7 B8 B9 A0 A4 A3 A2 A1 B1]
time 5580ms: Recalculated tau for process A5: old tau 100ms ==> new tau 193ms [Q A6 A7 A8 A9 B0 B2 B3 B5 B6 B7 B8 B9 A0 A4 A3 A2 A1 B1]
time 5580ms: Process A5 switching out of CPU; blocking on I/O until time 5601ms [Q A6 A7 A8 A9 B0 B2 B3 B5 B6 B7 B8 B9 A0 A4 A3 A2 A1 B1]
time 5584ms: Process A6 (tau 100ms) started using the CPU for 280ms burst [Q A7 A8 A9 B0 B2 B3 B5 B6 B7 B8 B9 A0 A4 A3 A2 A1 B1]
time 5601ms: Process A5 (tau 193ms) completed I/O; added to ready queue [Q A7 A8 A9 B0 B2 B3 B5 B6 B7 B8 B9 A0 A5 A4 A3 A2 A1 B1]
time 5608ms: Process B4 (tau 274ms) completed I/O; added to ready queue [Q A7 A8 A9 B0 B2 B3 B5 B6 B7 B8 B9 A0 A5 B4 A4 A3 A2 A1 B1]
time 5864ms: Process A6 (tau 100ms) completed a CPU burst; 17 bursts to go [Q A7 A8 A9 B0 B2 B3 B5 B6 B7 B8 B9 A0 A5 B4 A4 A3 A2 A1 B1]
time 5864ms: Recalculated tau for process A6: old tau 100ms ==> new tau 273ms [Q A7 A8 A9 B0 B2 B3 B5 B6 B7 B8 B9 A0 A5 B4 A4 A3 A2 A1 B1]
time 5864ms: Process A6 switching out of CPU; blocking on I/O until time 5940ms [Q A7 A8 A9 B0 B2 B3 B5 B6 B7 B8 B9 A0 A5 B4 A4 A3 A2 A1 B1]
time 5868ms: Process A7 (tau 100ms) started using the CPU for 84ms burst [Q A8 A9 B0 B2 B3 B5 B6 B7 B8 B9 A0 A5 B4 A4 A3 A2 A1 B1]
time 5940ms: Process A6 (tau 273ms) completed I/O; added to ready queue [Q A8 A9 B0 B2 B3 B5 B6 B7 B8 B9 A0 A5 A6 B4 A4 A3 A2 A1 B1]
time 5952ms: Process A7 (tau 100ms) completed a CPU burst; 18 bursts to go [Q A8 A9 B0 B2 B3 B5 B6 B7 B8 B9 A0 A5 A6 B4 A4 A3 A2 A1 B1]
time 5952ms: Recalculated tau for process A7: old tau 100ms ==> new tau 85ms [Q A8 A9 B0 B2 B3 B5 B6 B7 B8 B9 A0 A5 A6 B4 A4 A3 A2 A1 B1]
time 5952ms: Process A7 switching out of CPU; blocking on I/O until time 6005ms [Q A8 A9 B0 B2 B3 B5 B6 B7 B8 B9 A0 A5 A6 B4 A4 A3 A2 A1 B1]
time 5956ms: Process A8 (tau 100ms) started using the CPU for 420ms burst [Q A9 B0 B2 B3 B5 B6 B7 B8 B9 A0 A5 A6 B4 A4 A3 A2 A1 B1]
time 6005ms: Process A7 (tau 85ms) completed I/O; added to ready queue [Q A7 A9 B0 B2 B3 B5 B6 B7 B8 B9 A0 A5 A6 B4 A4 A3 A2 A1 B1]
time 6376ms: Process A8 (tau 100ms) completed a CPU burst; 7 bursts to go [Q A7 A9 B0 B2 B3 B5 B6 B7 B8 B9 A0 A5 A6 B4 A4 A3 A2 A1 B1]
time 6376ms: Recalculated tau for process A8: old tau 100ms ==> new tau 408ms [Q A7 A9 B0 B2 B3 B5 B6 B7 B8 B9 A0 A5 A6 B4 A4 A3 A2 A1 B1]
time 6376ms: Process A8 switching out of CPU; blocking on I/O until time 6434ms [Q A7 A9 B0 B2 B3 B5 B6 B7 B8 B9 A0 A5 A6 B4 A4 A3 A2 A1 B1]
time 6380ms: Process A7 (tau 85ms) started using the CPU for 768ms burst [Q A9 B0 B2 B3 B5 B6 B7 B8 B9 A0 A5 A6 B4 A4 A3 A2 A1 B1]
time 6434ms: Process A8 (tau 408ms) completed I/O; added to ready queue [Q A9 B0 B2 B3 B5 B6 B7 B8 B9 A0 A5 A6 B4 A4 A3 A8 A2 A1 B1]
time 7148ms: Process A7 (tau 85ms) completed a CPU burst; 17 bursts to go [Q A9 B0 B2 B3 B5 B6 B7 B8 B9 A0 A5 A6 B4 A4 A3 A8 A2 A1 B1]
time 7148ms: Recalculated tau for process A7: old tau 85ms ==> new tau 741ms [Q A9 B0 B2 B3 B5 B6 B7 B8 B9 A0 A5 A6 B4 A4 A3 A8 A2 A1 B1]
time 7148ms: Process A7 switching out of CPU; blocking on I/O until time 7273ms [Q A9 B0 B2 B3 B5 B6 B7 B8 B9 A0 A5 A6 B4 A4 A3 A8 A2 A1 B1]
time 7152ms: Process A9 (tau 100ms) started using the CPU for 360ms burst [Q B0 B2 B3 B5 B6 B7 B8 B9 A0 A5 A6 B4 A4 A3 A8 A2 A1 B1]
time 7273ms: Process A7 (tau 741ms) completed I/O; added to ready queue [Q B0 B2 B3 B5 B6 B7 B8 B9 A0 A5 A6 B4 A4 A3 A8 A2 A1 A7 B1]
time 7512ms: Process A9 (tau 100ms) completed a CPU burst; 31 bursts to go [Q B0 B2 B3 B5 B6 B7 B8 B9 A0 A5 A6 B4 A4 A3 A8 A2 A1 A7 B1]
time 7512ms: Recalculated tau for process A9: old tau 100ms ==> new tau 350ms [Q B0 B2 B3 B5 B6 B7 B8 B9 A0 A5 A6 B4 A4 A3 A8 A2 A1 A7 B1]
time 7512ms: Process A9 switching out of CPU; blocking on I/O until time 7556ms [Q B0 B2 B3 B5 B6 B7 B8 B9 A0 A5 A6 B4 A4 A3 A8 A2 A1 A7 B1]
time 7516ms: Process B0 (tau 100ms) started using the CPU for 216ms burst [Q B2 B3 B5 B6 B7 B8 B9 A0 A5 A6 B4 A4 A3 A8 A2 A1 A7 B1]
time 7556ms: Process A9 (tau 350ms) completed I/O; added to ready queue [Q B2 B3 B5 B6 B7 B8 B9 A0 A5 A6 B4 A4 A3 A9 A8 A2 A1 A7 B1]
time 7732ms: Process B0 (tau 100ms) completed a CPU burst; 18 bursts to go [Q B2 B3 B5 B6 B7 B8 B9 A0 A5 A6 B4 A4 A3 A9 A8 A2 A1 A7 B1]
time 7732ms: Recalculated tau for process B0: old tau 100ms ==> new tau 212ms [Q B2 B3 B5 B6 B7 B8 B9 A0 A5 A6 B4 A4 A3 A9 A8 A2 A1 A7 B1]
time 7732ms: Process B0 switching out of CPU; blocking on I/O until time 7885ms [Q B2 B3 B5 B6 B7 B8 B9 A0 A5 A6 B4 A4 A3 A9 A8 A2 A1 A7 B1]
time 7736ms: Process B2 (tau 100ms) started using the CPU for 122ms burst [Q B3 B5 B6 B7 B8 B9 A0 A5 A6 B4 A4 A3 A9 A8 A2 A1 A7 B1]
time 7858ms: Process B2 (tau 100ms) completed a CPU burst; 14 bursts to go [Q B3 B5 B6 B7 B8 B9 A0 A5 A6 B4 A4 A3 A9 A8 A2 A1 A7 B1]
time 7858ms: Recalculated tau for process B2: old tau 100ms ==> new tau 122ms [Q B3 B5 B6 B7 B8 B9 A0 A5 A6 B4 A4 A3 A9 A8 A2 A1 A7 B1]
time 7858ms: Process B2 switching out of CPU; blocking on I/O until time 8382ms [Q B3 B5 B6 B7 B8 B9 A0 A5 A6 B4 A4 A3 A9 A8 A2 A1 A7 B1]
time 7862ms: Process B3 (tau 100ms) started using the CPU for 51ms burst [Q B5 B6 B7 B8 B9 A0 A5 A6 B4 A4 A3 A9 A8 A2 A1 A7 B1]
time 7885ms: Process B0 (tau 212ms) completed I/O; added to ready queue [Q B5 B6 B7 B8 B9 A0 A5 B0 A6 B4 A4 A3 A9 A8 A2 A1 A7 B1]
time 7913ms: Process B3 (tau 100ms) completed a CPU burst; 21 bursts to go [Q B5 B6 B7 B8 B9 A0 A5 B0 A6 B4 A4 A3 A9 A8 A2 A1 A7 B1]
time 7913ms: Recalculated tau for process B3: old tau 100ms ==> new tau 53ms [Q B5 B6 B7 B8 B9 A0 A5 B0 A6 B4 A4 A3 A9 A8 A2 A1 A7 B1]
time 7913ms: Process B3 switching out of CPU; blocking on I/O until time 10253ms [Q B5 B6 B7 B8 B9 A0 A5 B0 A6 B4 A4 A3 A9 A8 A2 A1 A7 B1]
time 7917ms: Process B5 (tau 100ms) started using the CPU for 20ms burst [Q B6 B7 B8 B9 A0 A5 B0 A6 B4 A4 A3 A9 A8 A2 A1 A7 B1]
time 7937ms: Process B5 (tau 100ms) completed a CPU burst; 29 bursts to go [Q B6 B7 B8 B9 A0 A5 B0 A6 B4 A4 A3 A9 A8 A2 A1 A7 B1]
time 7937ms: Recalculated tau for process B5: old tau 100ms ==> new tau 24ms [Q B6 B7 B8 B9 A0 A5 B0 A6 B4 A4 A3 A9 A8 A2 A1 A7 B1]
time 7937ms: Process B5 switching out of CPU; blocking on I/O until time 8189ms [Q B6 B7 B8 B9 A0 A5 B0 A6 B4 A4 A3 A9 A8 A2 A1 A7 B1]
time 7941ms: Process B6 (tau 100ms) started using the CPU for 113ms burst [Q B7 B8 B9 A0 A5 B0 A6 B4 A4 A3 A9 A8 A2 A1 A7 B1]
time 8054ms: Process B6 (tau 100ms) completed a CPU burst; 4 bursts to go [Q B7 B8 B9 A0 A5 B0 A6 B4 A4 A3 A9 A8 A2 A1 A7 B1]
time 8054ms: Recalculated tau for process B6: old tau 100ms ==> new tau 113ms [Q B7 B8 B9 A0 A5 B0 A6 B4 A4 A3 A9 A8 A2 A1 A7 B1]
time 8054ms: Process B6 switching out of CPU; blocking on I/O until time 11282ms [Q B7 B8 B9 A0 A5 B0 A6 B4 A4 A3 A9 A8 A2 A1 A7 B1]
time 8058ms: Process B7 (tau 100ms) started using the CPU for 71ms burst [Q B8 B9 A0 A5 B0 A6 B4 A4 A3 A9 A8 A2 A1 A7 B1]
time 8129ms: Process B7 (tau 100ms) completed a CPU burst; 25 bursts to go [Q B8 B9 A0 A5 B0 A6 B4 A4 A3 A9 A8 A2 A1 A7 B1]
time 8129ms: Recalculated tau for process B7: old tau 100ms ==> new tau 73ms [Q B8 B9 A0 A5 B0 A6 B4 A4 A3 A9 A8 A2 A1 A7 B1]
time 8129ms: Process B7 switching out of CPU; blocking on I/O until time 11181ms [Q B8 B9 A0 A5 B0 A6 B4 A4 A3 A9 A8 A2 A1 A7 B1]
time 8133ms: Process B8 (tau 100ms) started using the CPU for 308ms burst [Q B9 A0 A5 B0 A6 B4 A4 A3 A9 A8 A2 A1 A7 B1]
time 8189ms: Process B5 (tau 24ms) completed I/O; added to ready queue [Q B5 B9 A0 A5 B0 A6 B4 A4 A3 A9 A8 A2 A1 A7 B1]
time 8382ms: Process B2 (tau 122ms) completed I/O; added to ready queue [Q B5 B9 B2 A0 A5 B0 A6 B4 A4 A3 A9 A8 A2 A1 A7 B1]
time 8441ms: Process B8 (tau 100ms) completed a CPU burst; 19 bursts to go [Q B5 B9 B2 A0 A5 B0 A6 B4 A4 A3 A9 A8 A2 A1 A7 B1]
time 8441ms: Recalculated tau for process B8: old tau 100ms ==> new tau 300ms [Q B5 B9 B2 A0 A5 B0 A6 B4 A4 A3 A9 A8 A2 A1 A7 B1]
time 8441ms: Process B8 switching out of CPU; blocking on I/O until time 10725ms [Q B5 B9 B2 A0 A5 B0 A6 B4 A4 A3 A9 A8 A2 A1 A7 B1]
time 8445ms: Process B5 (tau 24ms) started using the CPU for 85ms burst [Q B9 B2 A0 A5 B0 A6 B4 A4 A3 A9 A8 A2 A1 A7 B1]
time 8530ms: Process B5 (tau 24ms) completed a CPU burst; 28 bursts to go [Q B9 B2 A0 A5 B0 A6 B4 A4 A3 A9 A8 A2 A1 A7 B1]
time 8530ms: Recalculated tau for process B5: old tau 24ms ==> new tau 83ms [Q B9 B2 A0 A5 B0 A6 B4 A4 A3 A9 A8 A2 A1 A7 B1]
time 8530ms: Process B5 switching out of CPU; blocking on I/O until time 8774ms [Q B9 B2 A0 A5 B0 A6 B4 A4 A3 A9 A8 A2 A1 A7 B1]
time 8534ms: Process B9 (tau 100ms) started using the CPU for 22ms burst [Q B2 A0 A5 B0 A6 B4 A4 A3 A9 A8 A2 A1 A7 B1]
time 8556ms: Process B9 (tau 100ms) completed a CPU burst; 10 bursts to go [Q B2 A0 A5 B0 A6 B4 A4 A3 A9 A8 A2 A1 A7 B1]
time 8556ms: Recalculated tau for process B9: old tau 100ms ==> new tau 26ms [Q B2 A0 A5 B0 A6 B4 A4 A3 A9 A8 A2 A1 A7 B1]
time 8556ms: Process B9 switching out of CPU; blocking on I/O until time 9168ms [Q B2 A0 A5 B0 A6 B4 A4 A3 A9 A8 A2 A1 A7 B1]
time 8560ms: Process B2 (tau 122ms) started using the CPU for 183ms burst [Q A0 A5 B0 A6 B4 A4 A3 A9 A8 A2 A1 A7 B1]
time 8743ms: Process B2 (tau 122ms) completed a CPU burst; 13 bursts to go [Q A0 A5 B0 A6 B4 A4 A3 A9 A8 A2 A1 A7 B1]
time 8743ms: Recalculated tau for process B2: old tau 122ms ==> new tau 181ms [Q A0 A5 B0 A6 B4 A4 A3 A9 A8 A2 A1 A7 B1]
time 8743ms: Process B2 switching out of CPU; blocking on I/O until time 9059ms [Q A0 A5 B0 A6 B4 A4 A3 A9 A8 A2 A1 A7 B1]
time 8747ms: Process A0 (tau 193ms) started using the CPU for 1096ms burst [Q A5 B0 A6 B4 A4 A3 A9 A8 A2 A1 A7 B1]
time 8774ms: Process B5 (tau 83ms) completed I/O; added to ready queue [Q B5 A5 B0 A6 B4 A4 A3 A9 A8 A2 A1 A7 B1]
time 9059ms: Process B2 (tau 181ms) completed I/O; added to ready queue [Q B5 B2 A5 B0 A6 B4 A4 A3 A9 A8 A2 A1 A7 B1]
time 9168ms: Process B9 (tau 26ms) completed I/O; added to ready queue [Q B9 B5 B2 A5 B0 A6 B4 A4 A3 A9 A8 A2 A1 A7 B1]
time 9843ms: Process A0 (tau 193ms) completed a CPU burst; 28 bursts to go [Q B9 B5 B2 A5 B0 A6 B4 A4 A3 A9 A8 A2 A1 A7 B1]
time 9843ms: Recalculated tau for process A0: old tau 193ms ==> new tau 1060ms [Q B9 B5 B2 A5 B0 A6 B4 A4 A3 A9 A8 A2 A1 A7 B1]
time 9843ms: Process A0 switching out of CPU; blocking on I/O until time 9932ms [Q B9 B5 B2 A5 B0 A6 B4 A4 A3 A9 A8 A2 A1 A7 B1]
time 9847ms: Process B9 (tau 26ms) started using the CPU for 142ms burst [Q B5 B2 A5 B0 A6 B4 A4 A3 A9 A8 A2 A1 A7 B1]
time 9932ms: Process A0 (tau 1060ms) completed I/O; added to ready queue [Q B5 B2 A5 B0 A6 B4 A4 A3 A9 A8 A2 A1 A7 A0 B1]
time 9989ms: Process B9 (tau 26ms) completed a CPU burst; 9 bursts to go [Q B5 B2 A5 B0 A6 B4 A4 A3 A9 A8 A2 A1 A7 A0 B1]
time 9989ms: Recalculated tau for process B9: old tau 26ms ==> new tau 138ms [Q B5 B2 A5 B0 A6 B4 A4 A3 A9 A8 A2 A1 A7 A0 B1]
time 9989ms: Process B9 switching out of CPU; blocking on I/O until time 10065ms [Q B5 B2 A5 B0 A6 B4 A4 A3 A9 A8 A2 A1 A7 A0 B1]
time 9993ms: Process B5 (tau 83ms) started using the CPU for 20ms burst [Q B2 A5 B0 A6 B4 A4 A3 A9 A8 A2 A1 A7 A0 B1]
time 14057ms: Process A5 terminated [Q B5 B3 B6 B2 B9 A6 B4 A4 A3 B8 A9 A8 A2 A1 A7 A0 B0 B1]
time 17017ms: Process B6 terminated [Q A3 B8 A4 B4 B2 B9 B5 A9 A8 A2 A1 A7 A0 B0 B1]
time 23711ms: Process B9 terminated [Q A3 A1 A9 A6 A7 A8 A0 A4 B0 B1]
time 25768ms: Process B2 terminated [Q B4 A3 A1 A9 A6 A7 A2 A8 A0 A4 B0 B1]
time 34377ms: Process B4 terminated [Q B7 A9 B5 A6 A7 A2 A8 A3 A0 A4 B0 A1 B1]
time 43535ms: Process B8 terminated [Q B7 A2 A8 A3 A0 A4 B0 A6 A7 A1 A9 B1]
time 47428ms: Process B5 terminated [Q B3 B7 A2 A3 A0 A4 B0 A6 A7 A1 A9 A8 B1]
time 50836ms: Process B7 terminated [Q B3 A2 A3 A0 A4 B0 A6 A7 A1 A9 A8 B1]
time 50860ms: Process B3 terminated [Q A2 A3 A0 A4 B0 A6 A7 A1 A9 A8 B1]
time 58279ms: Process A4 terminated [Q A0 A3 A2 B0 A6 A7 A1 A9 A8 B1]
time 71110ms: Process A2 terminated [Q B0 A0 A6 A7 A1 A9 A3 A8 B1]
time 80989ms: Process B0 terminated [Q A6 A7 A1 A9 A3 A0 A8 B1]
time 85572ms: Process A6 terminated [Q A7 A1 A9 A3 A0 A8 B1]
time 88575ms: Process A1 terminated [Q A7 A3 A0 A8 B1]
time 89934ms: Process A3 terminated [Q A7 A9 A0 A8 B1]
time 92321ms: Process A0 terminated [Q A9 A7 A8 B1]
time 93520ms: Process A8 terminated [Q A7 B1]
time 96783ms: Process A7 terminated [Q A9]
time 106771ms: Process A9 terminated [Q B1]
time 107526ms: Process B1 terminated [Q empty]
time 107528ms: Simulator ended for SJF [Q empty]
SJF simulation completed

Simulating SRT
time 0ms: Simulator started for SRT [Q empty]
time 2ms: Process B4 (tau 100ms) arrived; added to ready queue [Q B4]
time 4ms: Process B4 (tau 100ms) started using the CPU for 8ms burst [Q empty]
time 9ms: Process B1 (tau 100ms) arrived; added to ready queue [Q B1]
time 12ms: Process B4 (tau 100ms) completed a CPU burst; 15 bursts to go [Q B1]
time 12ms: Recalculated tau for process B4: old tau 100ms ==> new tau 12ms [Q B1]
time 12ms: Process B4 switching out of CPU; blocking on I/O until time 982ms [Q B1]
time 16ms: Process B1 (tau 100ms) started using the CPU for 28ms burst [Q empty]
time 29ms: Process A6 (tau 100ms) arrived; added to ready queue [Q A6]
time 30ms: Process B7 (tau 100ms) arrived; added to ready queue [Q A6 B7]
time 41ms: Process A9 (tau 100ms) arrived; added to ready queue [Q A6 A9 B7]
time 44ms: Process B1 (tau 100ms) completed a CPU burst; 16 bursts to go [Q A6 A9 B7]
time 44ms: Recalculated tau for process B1: old tau 100ms ==> new tau 31ms [Q A6 A9 B7]
time 44ms: Process B1 switching out of CPU; blocking on I/O until time 264ms [Q A6 A9 B7]
time 45ms: Process A0 (tau 100ms) arrived; added to ready queue [Q A0 A6 A9 B7]
time 45ms: Process B0 (tau 100ms) arrived; added to ready queue [Q A0 A6 A9 B0 B7]
time 46ms: Process B2 (tau 100ms) arrived; added to ready queue [Q A0 A6 A9 B0 B2 B7]
time 47ms: Process A1 (tau 100ms) arrived; added to ready queue [Q A1 A6 A9 B0 B2 B7]
time 48ms: Process A0 (tau 100ms) started using the CPU for 196ms burst [Q A1 A6 A9 B0 B2 B7]
time 54ms: Process A7 (tau 100ms) arrived; added to ready queue [Q A1 A6 A7 A9 B0 B2 B7]
time 62ms: Process A8 (tau 100ms) arrived; added to ready queue [Q A1 A6 A7 A8 A9 B0 B2 B7]
time 92ms: Process A2 (tau 100ms) arrived; added to ready queue [Q A1 A2 A6 A7 A8 A9 B0 B2 B7]
time 95ms: Process B9 (tau 100ms) arrived; added to ready queue [Q A1 A2 A6 A7 A8 A9 B0 B2 B7 B9]
time 102ms: Process B6 (tau 100ms) arrived; added to ready queue [Q A1 A2 A6 A7 A8 A9 B0 B2 B6 B7 B9]
time 130ms: Process A5 (tau 100ms) arrived; added to ready queue [Q A1 A2 A5 A6 A7 A8 A9 B0 B2 B6 B7 B9]
time 140ms: Process B5 (tau 100ms) arrived; added to ready queue [Q A1 A2 A5 A6 A7 A8 A9 B0 B2 B5 B6 B7 B9]
time 157ms: Process A4 (tau 100ms) arrived; added to ready queue [Q A1 A2 A4 A5 A6 A7 A8 A9 B0 B2 B5 B6 B7 B9]
time 225ms: Process B8 (tau 100ms) arrived; added to ready queue [Q A1 A2 A4 A5 A6 A7 A8 A9 B0 B2 B5 B6 B7 B8 B9]
time 244ms: Process A0 (tau 100ms) completed a CPU burst; 29 bursts to go [Q A1 A2 A4 A5 A6 A7 A8 A9 B0 B2 B5 B6 B7 B8 B9]
time 244ms: Recalculated tau for process A0: old tau 100ms ==> new tau 193ms [Q A1 A2 A4 A5 A6 A7 A8 A9 B0 B2 B5 B6 B7 B8 B9]
time 244ms: Process A0 switching out of CPU; blocking on I/O until time 325ms [Q A1 A2 A4 A5 A6 A7 A8 A9 B0 B2 B5 B6 B7 B8 B9]
time 248ms: Process A1 (tau 100ms) started using the CPU for 632ms burst [Q A2 A4 A5 A6 A7 A8 A9 B0 B2 B5 B6 B7 B8 B9]
616
time 264ms: Process B1 (tau 31ms) completed I/O; preempting A1 (predicted remaining time 84ms) [Q B1 A2 A4 A5 A6 A7 A8 A9 B0 B2 B5 B6 B7 B8 B9]
time 268ms: Process B1 (tau 31ms) started using the CPU for 3004ms burst [Q A1 A2 A4 A5 A6 A7 A8 A9 B0 B2 B5 B6 B7 B8 B9]
time 271ms: Process B3 (tau 100ms) arrived; added to ready queue [Q A1 A2 A4 A5 A6 A7 A8 A9 B0 B2 B3 B5 B6 B7 B8 B9]
time 324ms: Process A3 (tau 100ms) arrived; added to ready queue [Q A1 A2 A3 A4 A5 A6 A7 A8 A9 B0 B2 B3 B5 B6 B7 B8 B9]
time 325ms: Process A0 (tau 193ms) completed I/O; added to ready queue [Q A1 A2 A3 A4 A5 A6 A7 A8 A9 B0 B2 B3 B5 B6 B7 B8 B9 A0]
time 982ms: Process B4 (tau 12ms) completed I/O; added to ready queue [Q B4 A1 A2 A3 A4 A5 A6 A7 A8 A9 B0 B2 B3 B5 B6 B7 B8 B9 A0]
time 3272ms: Process B1 (tau 31ms) completed a CPU burst; 15 bursts to go [Q B4 A1 A2 A3 A4 A5 A6 A7 A8 A9 B0 B2 B3 B5 B6 B7 B8 B9 A0]
time 3272ms: Recalculated tau for process B1: old tau 31ms ==> new tau 2886ms [Q B4 A1 A2 A3 A4 A5 A6 A7 A8 A9 B0 B2 B3 B5 B6 B7 B8 B9 A0]
time 3272ms: Process B1 switching out of CPU; blocking on I/O until time 3413ms [Q B4 A1 A2 A3 A4 A5 A6 A7 A8 A9 B0 B2 B3 B5 B6 B7 B8 B9 A0]
time 3276ms: Process B4 (tau 12ms) started using the CPU for 3ms burst [Q A1 A2 A3 A4 A5 A6 A7 A8 A9 B0 B2 B3 B5 B6 B7 B8 B9 A0]
time 3279ms: Process B4 (tau 12ms) completed a CPU burst; 14 bursts to go [Q A1 A2 A3 A4 A5 A6 A7 A8 A9 B0 B2 B3 B5 B6 B7 B8 B9 A0]
time 3279ms: Recalculated tau for process B4: old tau 12ms ==> new tau 4ms [Q A1 A2 A3 A4 A5 A6 A7 A8 A9 B0 B2 B3 B5 B6 B7 B8 B9 A0]
time 3279ms: Process B4 switching out of CPU; blocking on I/O until time 4377ms [Q A1 A2 A3 A4 A5 A6 A7 A8 A9 B0 B2 B3 B5 B6 B7 B8 B9 A0]
time 3283ms: Process A1 (tau 100ms) started using the CPU for remaining 0ms of 632ms burst [Q A2 A3 A4 A5 A6 A7 A8 A9 B0 B2 B3 B5 B6 B7 B8 B9 A0]
time 3413ms: Process B1 (tau 2886ms) completed I/O; added to ready queue [Q A2 A3 A4 A5 A6 A7 A8 A9 B0 B2 B3 B5 B6 B7 B8 B9 A0 B1]
time 3915ms: Process A1 (tau 100ms) completed a CPU burst; 11 bursts to go [Q A2 A3 A4 A5 A6 A7 A8 A9 B0 B2 B3 B5 B6 B7 B8 B9 A0 B1]
time 3915ms: Recalculated tau for process A1: old tau 100ms ==> new tau 611ms [Q A2 A3 A4 A5 A6 A7 A8 A9 B0 B2 B3 B5 B6 B7 B8 B9 A0 B1]
time 3915ms: Process A1 switching out of CPU; blocking on I/O until time 3955ms [Q A2 A3 A4 A5 A6 A7 A8 A9 B0 B2 B3 B5 B6 B7 B8 B9 A0 B1]
time 3919ms: Process A2 (tau 100ms) started using the CPU for 28ms burst [Q A3 A4 A5 A6 A7 A8 A9 B0 B2 B3 B5 B6 B7 B8 B9 A0 B1]
time 3947ms: Process A2 (tau 100ms) completed a CPU burst; 29 bursts to go [Q A3 A4 A5 A6 A7 A8 A9 B0 B2 B3 B5 B6 B7 B8 B9 A0 B1]
time 3947ms: Recalculated tau for process A2: old tau 100ms ==> new tau 31ms [Q A3 A4 A5 A6 A7 A8 A9 B0 B2 B3 B5 B6 B7 B8 B9 A0 B1]
time 3947ms: Process A2 switching out of CPU; blocking on I/O until time 3962ms [Q A3 A4 A5 A6 A7 A8 A9 B0 B2 B3 B5 B6 B7 B8 B9 A0 B1]
time 3951ms: Process A3 (tau 100ms) started using the CPU for 96ms burst [Q A4 A5 A6 A7 A8 A9 B0 B2 B3 B5 B6 B7 B8 B9 A0 B1]
time 3955ms: Process A1 (tau 611ms) completed I/O; added to ready queue [Q A4 A5 A6 A7 A8 A9 B0 B2 B3 B5 B6 B7 B8 B9 A0 A1 B1]
85
time 3962ms: Process A2 (tau 31ms) completed I/O; preempting A3 (predicted remaining time 89ms) [Q A2 A4 A5 A6 A7 A8 A9 B0 B2 B3 B5 B6 B7 B8 B9 A0 A1 B1]
time 3966ms: Process A2 (tau 31ms) started using the CPU for 444ms burst [Q A3 A4 A5 A6 A7 A8 A9 B0 B2 B3 B5 B6 B7 B8 B9 A0 A1 B1]
time 4377ms: Process B4 (tau 4ms) completed I/O; added to ready queue [Q B4 A3 A4 A5 A6 A7 A8 A9 B0 B2 B3 B5 B6 B7 B8 B9 A0 A1 B1]
time 4410ms: Process A2 (tau 31ms) completed a CPU burst; 28 bursts to go [Q B4 A3 A4 A5 A6 A7 A8 A9 B0 B2 B3 B5 B6 B7 B8 B9 A0 A1 B1]
time 4410ms: Recalculated tau for process A2: old tau 31ms ==> new tau 428ms [Q B4 A3 A4 A5 A6 A7 A8 A9 B0 B2 B3 B5 B6 B7 B8 B9 A0 A1 B1]
time 4410ms: Process A2 switching out of CPU; blocking on I/O until time 4871ms [Q B4 A3 A4 A5 A6 A7 A8 A9 B0 B2 B3 B5 B6 B7 B8 B9 A0 A1 B1]
time 4414ms: Process B4 (tau 4ms) started using the CPU for 285ms burst [Q A3 A4 A5 A6 A7 A8 A9 B0 B2 B3 B5 B6 B7 B8 B9 A0 A1 B1]
time 4699ms: Process B4 (tau 4ms) completed a CPU burst; 13 bursts to go [Q A3 A4 A5 A6 A7 A8 A9 B0 B2 B3 B5 B6 B7 B8 B9 A0 A1 B1]
time 4699ms: Recalculated tau for process B4: old tau 4ms ==> new tau 274ms [Q A3 A4 A5 A6 A7 A8 A9 B0 B2 B3 B5 B6 B7 B8 B9 A0 A1 B1]
time 4699ms: Process B4 switching out of CPU; blocking on I/O until time 4925ms [Q A3 A4 A5 A6 A7 A8 A9 B0 B2 B3 B5 B6 B7 B8 B9 A0 A1 B1]
time 4703ms: Process A3 (tau 100ms) started using the CPU for remaining 0ms of 96ms burst [Q A4 A5 A6 A7 A8 A9 B0 B2 B3 B5 B6 B7 B8 B9 A0 A1 B1]
time 4799ms: Process A3 (tau 100ms) completed a CPU burst; 25 bursts to go [Q A4 A5 A6 A7 A8 A9 B0 B2 B3 B5 B6 B7 B8 B9 A0 A1 B1]
time 4799ms: Recalculated tau for process A3: old tau 100ms ==> new tau 97ms [Q A4 A5 A6 A7 A8 A9 B0 B2 B3 B5 B6 B7 B8 B9 A0 A1 B1]
time 4799ms: Process A3 switching out of CPU; blocking on I/O until time 5171ms [Q A4 A5 A6 A7 A8 A9 B0 B2 B3 B5 B6 B7 B8 B9 A0 A1 B1]
time 4803ms: Process A4 (tau 100ms) started using the CPU for 300ms burst [Q A5 A6 A7 A8 A9 B0 B2 B3 B5 B6 B7 B8 B9 A0 A1 B1]
time 4871ms: Process A2 (tau 428ms) completed I/O; added to ready queue [Q A5 A6 A7 A8 A9 B0 B2 B3 B5 B6 B7 B8 B9 A0 A2 A1 B1]
time 4925ms: Process B4 (tau 274ms) completed I/O; added to ready queue [Q A5 A6 A7 A8 A9 B0 B2 B3 B5 B6 B7 B8 B9 A0 B4 A2 A1 B1]
time 5103ms: Process A4 (tau 100ms) completed a CPU burst; 3 bursts to go [Q A5 A6 A7 A8 A9 B0 B2 B3 B5 B6 B7 B8 B9 A0 B4 A2 A1 B1]
time 5103ms: Recalculated tau for process A4: old tau 100ms ==> new tau 292ms [Q A5 A6 A7 A8 A9 B0 B2 B3 B5 B6 B7 B8 B9 A0 B4 A2 A1 B1]
time 5103ms: Process A4 switching out of CPU; blocking on I/O until time 5194ms [Q A5 A6 A7 A8 A9 B0 B2 B3 B5 B6 B7 B8 B9 A0 B4 A2 A1 B1]
time 5107ms: Process A5 (tau 100ms) started using the CPU for 196ms burst [Q A6 A7 A8 A9 B0 B2 B3 B5 B6 B7 B8 B9 A0 B4 A2 A1 B1]
time 5171ms: Process A3 (tau 97ms) completed I/O; added to ready queue [Q A3 A6 A7 A8 A9 B0 B2 B3 B5 B6 B7 B8 B9 A0 B4 A2 A1 B1]
time 5194ms: Process A4 (tau 292ms) completed I/O; added to ready queue [Q A3 A6 A7 A8 A9 B0 B2 B3 B5 B6 B7 B8 B9 A0 B4 A4 A2 A1 B1]
time 5303ms: Process A5 (tau 100ms) completed a CPU burst; 4 bursts to go [Q A3 A6 A7 A8 A9 B0 B2 B3 B5 B6 B7 B8 B9 A0 B4 A4 A2 A1 B1]
time 5303ms: Recalculated tau for process A5: old tau 100ms ==> new tau 193ms [Q A3 A6 A7 A8 A9 B0 B2 B3 B5 B6 B7 B8 B9 A0 B4 A4 A2 A1 B1]
time 5303ms: Process A5 switching out of CPU; blocking on I/O until time 5322ms [Q A3 A6 A7 A8 A9 B0 B2 B3 B5 B6 B7 B8 B9 A0 B4 A4 A2 A1 B1]
time 5307ms: Process A3 (tau 97ms) started using the CPU for 308ms burst [Q A6 A7 A8 A9 B0 B2 B3 B5 B6 B7 B8 B9 A0 B4 A4 A2 A1 B1]
time 5322ms: Process A5 (tau 193ms) completed I/O; added to ready queue [Q A6 A7 A8 A9 B0 B2 B3 B5 B6 B7 B8 B9 A0 A5 B4 A4 A2 A1 B1]
time 5615ms: Process A3 (tau 97ms) completed a CPU burst; 24 bursts to go [Q A6 A7 A8 A9 B0 B2 B3 B5 B6 B7 B8 B9 A0 A5 B4 A4 A2 A1 B1]
time 5615ms: Recalculated tau for process A3: old tau 97ms ==> new tau 300ms [Q A6 A7 A8 A9 B0 B2 B3 B5 B6 B7 B8 B9 A0 A5 B4 A4 A2 A1 B1]
time 5615ms: Process A3 switching out of CPU; blocking on I/O until time 5705ms [Q A6 A7 A8 A9 B0 B2 B3 B5 B6 B7 B8 B9 A0 A5 B4 A4 A2 A1 B1]
time 5619ms: Process A6 (tau 100ms) started using the CPU for 280ms burst [Q A7 A8 A9 B0 B2 B3 B5 B6 B7 B8 B9 A0 A5 B4 A4 A2 A1 B1]
time 5705ms: Process A3 (tau 300ms) completed I/O; added to ready queue [Q A7 A8 A9 B0 B2 B3 B5 B6 B7 B8 B9 A0 A5 B4 A4 A3 A2 A1 B1]
time 5899ms: Process A6 (tau 100ms) completed a CPU burst; 17 bursts to go [Q A7 A8 A9 B0 B2 B3 B5 B6 B7 B8 B9 A0 A5 B4 A4 A3 A2 A1 B1]
time 5899ms: Recalculated tau for process A6: old tau 100ms ==> new tau 273ms [Q A7 A8 A9 B0 B2 B3 B5 B6 B7 B8 B9 A0 A5 B4 A4 A3 A2 A1 B1]
time 5899ms: Process A6 switching out of CPU; blocking on I/O until time 5973ms [Q A7 A8 A9 B0 B2 B3 B5 B6 B7 B8 B9 A0 A5 B4 A4 A3 A2 A1 B1]
time 5903ms: Process A7 (tau 100ms) started using the CPU for 84ms burst [Q A8 A9 B0 B2 B3 B5 B6 B7 B8 B9 A0 A5 B4 A4 A3 A2 A1 B1]
time 5973ms: Process A6 (tau 273ms) completed I/O; added to ready queue [Q A8 A9 B0 B2 B3 B5 B6 B7 B8 B9 A0 A5 A6 B4 A4 A3 A2 A1 B1]
time 5987ms: Process A7 (tau 100ms) completed a CPU burst; 18 bursts to go [Q A8 A9 B0 B2 B3 B5 B6 B7 B8 B9 A0 A5 A6 B4 A4 A3 A2 A1 B1]
time 5987ms: Recalculated tau for process A7: old tau 100ms ==> new tau 85ms [Q A8 A9 B0 B2 B3 B5 B6 B7 B8 B9 A0 A5 A6 B4 A4 A3 A2 A1 B1]
time 5987ms: Process A7 switching out of CPU; blocking on I/O until time 6038ms [Q A8 A9 B0 B2 B3 B5 B6 B7 B8 B9 A0 A5 A6 B4 A4 A3 A2 A1 B1]
time 5991ms: Process A8 (tau 100ms) started using the CPU for 420ms burst [Q A9 B0 B2 B3 B5 B6 B7 B8 B9 A0 A5 A6 B4 A4 A3 A2 A1 B1]
time 6038ms: Process A7 (tau 85ms) completed I/O; added to ready queue [Q A7 A9 B0 B2 B3 B5 B6 B7 B8 B9 A0 A5 A6 B4 A4 A3 A2 A1 B1]
time 6411ms: Process A8 (tau 100ms) completed a CPU burst; 7 bursts to go [Q A7 A9 B0 B2 B3 B5 B6 B7 B8 B9 A0 A5 A6 B4 A4 A3 A2 A1 B1]
time 6411ms: Recalculated tau for process A8: old tau 100ms ==> new tau 408ms [Q A7 A9 B0 B2 B3 B5 B6 B7 B8 B9 A0 A5 A6 B4 A4 A3 A2 A1 B1]
time 6411ms: Process A8 switching out of CPU; blocking on I/O until time 6467ms [Q A7 A9 B0 B2 B3 B5 B6 B7 B8 B9 A0 A5 A6 B4 A4 A3 A2 A1 B1]
time 6415ms: Process A7 (tau 85ms) started using the CPU for 768ms burst [Q A9 B0 B2 B3 B5 B6 B7 B8 B9 A0 A5 A6 B4 A4 A3 A2 A1 B1]
time 6467ms: Process A8 (tau 408ms) completed I/O; added to ready queue [Q A9 B0 B2 B3 B5 B6 B7 B8 B9 A0 A5 A6 B4 A4 A3 A8 A2 A1 B1]
time 7183ms: Process A7 (tau 85ms) completed a CPU burst; 17 bursts to go [Q A9 B0 B2 B3 B5 B6 B7 B8 B9 A0 A5 A6 B4 A4 A3 A8 A2 A1 B1]
time 7183ms: Recalculated tau for process A7: old tau 85ms ==> new tau 741ms [Q A9 B0 B2 B3 B5 B6 B7 B8 B9 A0 A5 A6 B4 A4 A3 A8 A2 A1 B1]
time 7183ms: Process A7 switching out of CPU; blocking on I/O until time 7306ms [Q A9 B0 B2 B3 B5 B6 B7 B8 B9 A0 A5 A6 B4 A4 A3 A8 A2 A1 B1]
time 7187ms: Process A9 (tau 100ms) started using the CPU for 360ms burst [Q B0 B2 B3 B5 B6 B7 B8 B9 A0 A5 A6 B4 A4 A3 A8 A2 A1 B1]
time 7306ms: Process A7 (tau 741ms) completed I/O; added to ready queue [Q B0 B2 B3 B5 B6 B7 B8 B9 A0 A5 A6 B4 A4 A3 A8 A2 A1 A7 B1]
time 7547ms: Process A9 (tau 100ms) completed a CPU burst; 31 bursts to go [Q B0 B2 B3 B5 B6 B7 B8 B9 A0 A5 A6 B4 A4 A3 A8 A2 A1 A7 B1]
time 7547ms: Recalculated tau for process A9: old tau 100ms ==> new tau 350ms [Q B0 B2 B3 B5 B6 B7 B8 B9 A0 A5 A6 B4 A4 A3 A8 A2 A1 A7 B1]
time 7547ms: Process A9 switching out of CPU; blocking on I/O until time 7589ms [Q B0 B2 B3 B5 B6 B7 B8 B9 A0 A5 A6 B4 A4 A3 A8 A2 A1 A7 B1]
time 7551ms: Process B0 (tau 100ms) started using the CPU for 216ms burst [Q B2 B3 B5 B6 B7 B8 B9 A0 A5 A6 B4 A4 A3 A8 A2 A1 A7 B1]
time 7589ms: Process A9 (tau 350ms) completed I/O; added to ready queue [Q B2 B3 B5 B6 B7 B8 B9 A0 A5 A6 B4 A4 A3 A9 A8 A2 A1 A7 B1]
time 7767ms: Process B0 (tau 100ms) completed a CPU burst; 18 bursts to go [Q B2 B3 B5 B6 B7 B8 B9 A0 A5 A6 B4 A4 A3 A9 A8 A2 A1 A7 B1]
time 7767ms: Recalculated tau for process B0: old tau 100ms ==> new tau 212ms [Q B2 B3 B5 B6 B7 B8 B9 A0 A5 A6 B4 A4 A3 A9 A8 A2 A1 A7 B1]
time 7767ms: Process B0 switching out of CPU; blocking on I/O until time 7918ms [Q B2 B3 B5 B6 B7 B8 B9 A0 A5 A6 B4 A4 A3 A9 A8 A2 A1 A7 B1]
time 7771ms: Process B2 (tau 100ms) started using the CPU for 122ms burst [Q B3 B5 B6 B7 B8 B9 A0 A5 A6 B4 A4 A3 A9 A8 A2 A1 A7 B1]
time 7893ms: Process B2 (tau 100ms) completed a CPU burst; 14 bursts to go [Q B3 B5 B6 B7 B8 B9 A0 A5 A6 B4 A4 A3 A9 A8 A2 A1 A7 B1]
time 7893ms: Recalculated tau for process B2: old tau 100ms ==> new tau 122ms [Q B3 B5 B6 B7 B8 B9 A0 A5 A6 B4 A4 A3 A9 A8 A2 A1 A7 B1]
time 7893ms: Process B2 switching out of CPU; blocking on I/O until time 8415ms [Q B3 B5 B6 B7 B8 B9 A0 A5 A6 B4 A4 A3 A9 A8 A2 A1 A7 B1]
time 7897ms: Process B3 (tau 100ms) started using the CPU for 51ms burst [Q B5 B6 B7 B8 B9 A0 A5 A6 B4 A4 A3 A9 A8 A2 A1 A7 B1]
time 7918ms: Process B0 (tau 212ms) completed I/O; added to ready queue [Q B5 B6 B7 B8 B9 A0 A5 B0 A6 B4 A4 A3 A9 A8 A2 A1 A7 B1]
time 7948ms: Process B3 (tau 100ms) completed a CPU burst; 21 bursts to go [Q B5 B6 B7 B8 B9 A0 A5 B0 A6 B4 A4 A3 A9 A8 A2 A1 A7 B1]
time 7948ms: Recalculated tau for process B3: old tau 100ms ==> new tau 53ms [Q B5 B6 B7 B8 B9 A0 A5 B0 A6 B4 A4 A3 A9 A8 A2 A1 A7 B1]
time 7948ms: Process B3 switching out of CPU; blocking on I/O until time 10286ms [Q B5 B6 B7 B8 B9 A0 A5 B0 A6 B4 A4 A3 A9 A8 A2 A1 A7 B1]
time 7952ms: Process B5 (tau 100ms) started using the CPU for 20ms burst [Q B6 B7 B8 B9 A0 A5 B0 A6 B4 A4 A3 A9 A8 A2 A1 A7 B1]
time 7972ms: Process B5 (tau 100ms) completed a CPU burst; 29 bursts to go [Q B6 B7 B8 B9 A0 A5 B0 A6 B4 A4 A3 A9 A8 A2 A1 A7 B1]
time 7972ms: Recalculated tau for process B5: old tau 100ms ==> new tau 24ms [Q B6 B7 B8 B9 A0 A5 B0 A6 B4 A4 A3 A9 A8 A2 A1 A7 B1]
time 7972ms: Process B5 switching out of CPU; blocking on I/O until time 8222ms [Q B6 B7 B8 B9 A0 A5 B0 A6 B4 A4 A3 A9 A8 A2 A1 A7 B1]
time 7976ms: Process B6 (tau 100ms) started using the CPU for 113ms burst [Q B7 B8 B9 A0 A5 B0 A6 B4 A4 A3 A9 A8 A2 A1 A7 B1]
time 8089ms: Process B6 (tau 100ms) completed a CPU burst; 4 bursts to go [Q B7 B8 B9 A0 A5 B0 A6 B4 A4 A3 A9 A8 A2 A1 A7 B1]
time 8089ms: Recalculated tau for process B6: old tau 100ms ==> new tau 113ms [Q B7 B8 B9 A0 A5 B0 A6 B4 A4 A3 A9 A8 A2 A1 A7 B1]
time 8089ms: Process B6 switching out of CPU; blocking on I/O until time 11315ms [Q B7 B8 B9 A0 A5 B0 A6 B4 A4 A3 A9 A8 A2 A1 A7 B1]
time 8093ms: Process B7 (tau 100ms) started using the CPU for 71ms burst [Q B8 B9 A0 A5 B0 A6 B4 A4 A3 A9 A8 A2 A1 A7 B1]
time 8164ms: Process B7 (tau 100ms) completed a CPU burst; 25 bursts to go [Q B8 B9 A0 A5 B0 A6 B4 A4 A3 A9 A8 A2 A1 A7 B1]
time 8164ms: Recalculated tau for process B7: old tau 100ms ==> new tau 73ms [Q B8 B9 A0 A5 B0 A6 B4 A4 A3 A9 A8 A2 A1 A7 B1]
time 8164ms: Process B7 switching out of CPU; blocking on I/O until time 11214ms [Q B8 B9 A0 A5 B0 A6 B4 A4 A3 A9 A8 A2 A1 A7 B1]
time 8168ms: Process B8 (tau 100ms) started using the CPU for 308ms burst [Q B9 A0 A5 B0 A6 B4 A4 A3 A9 A8 A2 A1 A7 B1]
254
time 8222ms: Process B5 (tau 24ms) completed I/O; preempting B8 (predicted remaining time 46ms) [Q B5 B9 A0 A5 B0 A6 B4 A4 A3 A9 A8 A2 A1 A7 B1]
time 8226ms: Process B5 (tau 24ms) started using the CPU for 85ms burst [Q B8 B9 A0 A5 B0 A6 B4 A4 A3 A9 A8 A2 A1 A7 B1]
time 8311ms: Process B5 (tau 24ms) completed a CPU burst; 28 bursts to go [Q B8 B9 A0 A5 B0 A6 B4 A4 A3 A9 A8 A2 A1 A7 B1]
time 8311ms: Recalculated tau for process B5: old tau 24ms ==> new tau 83ms [Q B8 B9 A0 A5 B0 A6 B4 A4 A3 A9 A8 A2 A1 A7 B1]
time 8311ms: Process B5 switching out of CPU; blocking on I/O until time 8553ms [Q B8 B9 A0 A5 B0 A6 B4 A4 A3 A9 A8 A2 A1 A7 B1]
time 8315ms: Process B8 (tau 100ms) started using the CPU for remaining 0ms of 308ms burst [Q B9 A0 A5 B0 A6 B4 A4 A3 A9 A8 A2 A1 A7 B1]
time 8415ms: Process B2 (tau 122ms) completed I/O; added to ready queue [Q B9 B2 A0 A5 B0 A6 B4 A4 A3 A9 A8 A2 A1 A7 B1]
time 8553ms: Process B5 (tau 83ms) completed I/O; added to ready queue [Q B5 B9 B2 A0 A5 B0 A6 B4 A4 A3 A9 A8 A2 A1 A7 B1]
time 8623ms: Process B8 (tau 100ms) completed a CPU burst; 19 bursts to go [Q B5 B9 B2 A0 A5 B0 A6 B4 A4 A3 A9 A8 A2 A1 A7 B1]
time 8623ms: Recalculated tau for process B8: old tau 100ms ==> new tau 300ms [Q B5 B9 B2 A0 A5 B0 A6 B4 A4 A3 A9 A8 A2 A1 A7 B1]
time 8623ms: Process B8 switching out of CPU; blocking on I/O until time 10905ms [Q B5 B9 B2 A0 A5 B0 A6 B4 A4 A3 A9 A8 A2 A1 A7 B1]
time 8627ms: Process B5 (tau 83ms) started using the CPU for 20ms burst [Q B9 B2 A0 A5 B0 A6 B4 A4 A3 A9 A8 A2 A1 A7 B1]
time 8647ms: Process B5 (tau 83ms) completed a CPU burst; 27 bursts to go [Q B9 B2 A0 A5 B0 A6 B4 A4 A3 A9 A8 A2 A1 A7 B1]
time 8647ms: Recalculated tau for process B5: old tau 83ms ==> new tau 23ms [Q B9 B2 A0 A5 B0 A6 B4 A4 A3 A9 A8 A2 A1 A7 B1]
time 8647ms: Process B5 switching out of CPU; blocking on I/O until time 9073ms [Q B9 B2 A0 A5 B0 A6 B4 A4 A3 A9 A8 A2 A1 A7 B1]
time 8651ms: Process B9 (tau 100ms) started using the CPU for 22ms burst [Q B2 A0 A5 B0 A6 B4 A4 A3 A9 A8 A2 A1 A7 B1]
time 8673ms: Process B9 (tau 100ms) completed a CPU burst; 10 bursts to go [Q B2 A0 A5 B0 A6 B4 A4 A3 A9 A8 A2 A1 A7 B1]
time 8673ms: Recalculated tau for process B9: old tau 100ms ==> new tau 26ms [Q B2 A0 A5 B0 A6 B4 A4 A3 A9 A8 A2 A1 A7 B1]
time 8673ms: Process B9 switching out of CPU; blocking on I/O until time 9283ms [Q B2 A0 A5 B0 A6 B4 A4 A3 A9 A8 A2 A1 A7 B1]
time 8677ms: Process B2 (tau 122ms) started using the CPU for 183ms burst [Q A0 A5 B0 A6 B4 A4 A3 A9 A8 A2 A1 A7 B1]
time 8860ms: Process B2 (tau 122ms) completed a CPU burst; 13 bursts to go [Q A0 A5 B0 A6 B4 A4 A3 A9 A8 A2 A1 A7 B1]
time 8860ms: Recalculated tau for process B2: old tau 122ms ==> new tau 181ms [Q A0 A5 B0 A6 B4 A4 A3 A9 A8 A2 A1 A7 B1]
time 8860ms: Process B2 switching out of CPU; blocking on I/O until time 9174ms [Q A0 A5 B0 A6 B4 A4 A3 A9 A8 A2 A1 A7 B1]
time 8864ms: Process A0 (tau 193ms) started using the CPU for 1096ms burst [Q A5 B0 A6 B4 A4 A3 A9 A8 A2 A1 A7 B1]
time 9073ms: Process B5 (tau 23ms) completed I/O; added to ready queue [Q B5 A5 B0 A6 B4 A4 A3 A9 A8 A2 A1 A7 B1]
time 9174ms: Process B2 (tau 181ms) completed I/O; added to ready queue [Q B5 B2 A5 B0 A6 B4 A4 A3 A9 A8 A2 A1 A7 B1]
time 9283ms: Process B9 (tau 26ms) completed I/O; added to ready queue [Q B5 B9 B2 A5 B0 A6 B4 A4 A3 A9 A8 A2 A1 A7 B1]
time 9960ms: Process A0 (tau 193ms) completed a CPU burst; 28 bursts to go [Q B5 B9 B2 A5 B0 A6 B4 A4 A3 A9 A8 A2 A1 A7 B1]
time 9960ms: Recalculated tau for process A0: old tau 193ms ==> new tau 1060ms [Q B5 B9 B2 A5 B0 A6 B4 A4 A3 A9 A8 A2 A1 A7 B1]
time 9960ms: Process A0 switching out of CPU; blocking on I/O until time 10047ms [Q B5 B9 B2 A5 B0 A6 B4 A4 A3 A9 A8 A2 A1 A7 B1]
time 9964ms: Process B5 (tau 23ms) started using the CPU for 14ms burst [Q B9 B2 A5 B0 A6 B4 A4 A3 A9 A8 A2 A1 A7 B1]
time 9978ms: Process B5 (tau 23ms) completed a CPU burst; 26 bursts to go [Q B9 B2 A5 B0 A6 B4 A4 A3 A9 A8 A2 A1 A7 B1]
time 9978ms: Recalculated tau for process B5: old tau 23ms ==> new tau 15ms [Q B9 B2 A5 B0 A6 B4 A4 A3 A9 A8 A2 A1 A7 B1]
time 9978ms: Process B5 switching out of CPU; blocking on I/O until time 11100ms [Q B9 B2 A5 B0 A6 B4 A4 A3 A9 A8 A2 A1 A7 B1]
time 9982ms: Process B9 (tau 26ms) started using the CPU for 142ms burst [Q B2 A5 B0 A6 B4 A4 A3 A9 A8 A2 A1 A7 B1]
167
104
46
94
164
time 14424ms: Process A5 terminated [Q B5 B3 B6 B2 B9 A6 B4 A4 A3 B8 A9 A8 A2 A1 A7 A0 B0 B1]
57
54
98
78
70
57
time 16592ms: Process B6 terminated [Q B2 B4 A4 A3 B8 A6 A9 A8 A2 A1 A7 A0 B0 B1]
48
737
61
48
27
715
575
150
164
0
time 22485ms: Process B9 terminated [Q B8 A8 A2 A3 A1 A9 A6 A7 A0 A4 B0 B1]
724
277
724
763
8
808
time 24014ms: Process B2 terminated [Q A8 A2 B5 A3 A1 A9 A6 A7 A0 A4 B0 B1]
50
546
394
545
108
92
158
176
194
111
110
3
105
120
175
102
time 31308ms: Process B4 terminated [Q A3 B5 A1 A9 A6 A7 A2 A8 A0 A4 B0 B1]
11
295
94
196
652
210
86
246
154
86
82
25
61
274
469
510
281
289
240
226
time 38006ms: Process B5 terminated [Q A1 A9 B7 A6 A7 A2 A8 A3 A0 A4 B0 B1]
191
time 40138ms: Process B8 terminated [Q A9 B7 A6 A7 A2 A8 A3 A0 A4 B0 A1 B1]
35
351
77
177
142
613
706
1627
223
210
122
1581
503
time 44922ms: Process B3 terminated [Q A6 A9 A7 A2 A8 A3 A0 A4 B0 A1 B1]
450
1656
1665
time 47454ms: Process B7 terminated [Q A9 A7 A2 A8 A3 A0 A4 B0 A6 A1 B1]
127
15
102
64
161
414
267
2
234
86
221
231
194
251
181
244
98
44
248
208
35
221
169
106
107
163
163
time 64612ms: Process A2 terminated [Q A3 A0 A4 B0 A6 A7 A1 A9 A8 B1]
887
779
840
48
197
348
307
410
363
274
453
201
97
time 75387ms: Process A4 terminated [Q B0 A6 A7 A1 A9 A3 A8 B1]
51
290
259
130
203
85
533
39
76
98
128
310
244
129
164
335
8
86
86
290
73
107
103
32
27
129
118
118
454
651
time 92065ms: Process B0 terminated [Q A6 A7 A1 A9 A3 A0 A8 B1]
446
422
346
461
344
460
255
time 96326ms: Process A6 terminated [Q A7 A1 A9 A3 A0 A8 B1]
0
539
535
455
530
565
351
351
437
558
571
499
481
459
539
time 101722ms: Process A7 terminated [Q A1 A9 A3 A0 A8 B1]
41
75
251
841
328
171
time 106878ms: Process A1 terminated [Q A9 A3 A0 A8 B1]
315
209
157
time 108624ms: Process A3 terminated [Q A0 A8 B1]
405
493
484
time 111241ms: Process A0 terminated [Q A9 A8 B1]
19
62
108
time 114319ms: Process A8 terminated [Q B1]
190
979
180
667
time 122258ms: Process A9 terminated [Q empty]
time 123271ms: Process B1 terminated [Q empty]
time 123273ms: Simulator ended for SRT [Q empty]
SRT simulation completed

Simulating RR
time 0ms: Simulator started for RR [Q empty]
time 2ms: Process B4 arrived; added to ready queue [Q B4]
time 4ms: Process B4 started using the CPU for 8ms burst [Q empty]
time 9ms: Process B1 arrived; added to ready queue [Q B1]
time 12ms: Process B4 completed a CPU burst; 15 bursts to go [Q B1]
time 12ms: Process B4 switching out of CPU; blocking on I/O until time 982ms [Q B1]
time 15ms: Process B1 started using the CPU for 28ms burst [Q empty]
time 29ms: Process A6 arrived; added to ready queue [Q A6]
time 30ms: Process B7 arrived; added to ready queue [Q A6 B7]
time 41ms: Process A9 arrived; added to ready queue [Q A6 B7 A9]
time 43ms: Process B1 completed a CPU burst; 16 bursts to go [Q A6 B7 A9]
time 43ms: Process B1 switching out of CPU; blocking on I/O until time 263ms [Q A6 B7 A9]
time 45ms: Process A0 arrived; added to ready queue [Q B7 A9 A0]
time 45ms: Process B0 arrived; added to ready queue [Q B7 A9 A0 B0]
time 46ms: Process B2 arrived; added to ready queue [Q B7 A9 A0 B0 B2]
time 46ms: Process A6 started using the CPU for 280ms burst [Q B7 A9 A0 B0 B2]
time 47ms: Process A1 arrived; added to ready queue [Q B7 A9 A0 B0 B2 A1]
time 54ms: Process A7 arrived; added to ready queue [Q B7 A9 A0 B0 B2 A1 A7]
time 62ms: Process A8 arrived; added to ready queue [Q B7 A9 A0 B0 B2 A1 A7 A8]
time 92ms: Process A2 arrived; added to ready queue [Q B7 A9 A0 B0 B2 A1 A7 A8 A2]
time 95ms: Process B9 arrived; added to ready queue [Q B7 A9 A0 B0 B2 A1 A7 A8 A2 B9]
time 102ms: Process B6 arrived; added to ready queue [Q B7 A9 A0 B0 B2 A1 A7 A8 A2 B9 B6]
time 110ms: Time slice expired; preempting process A6 with 216ms remaining [Q B7 A9 A0 B0 B2 A1 A7 A8 A2 B9 B6]
time 114ms: Process B7 started using the CPU for 71ms burst [Q A9 A0 B0 B2 A1 A7 A8 A2 B9 B6 A6]
time 130ms: Process A5 arrived; added to ready queue [Q A9 A0 B0 B2 A1 A7 A8 A2 B9 B6 A6 A5]
time 140ms: Process B5 arrived; added to ready queue [Q A9 A0 B0 B2 A1 A7 A8 A2 B9 B6 A6 A5 B5]
time 157ms: Process A4 arrived; added to ready queue [Q A9 A0 B0 B2 A1 A7 A8 A2 B9 B6 A6 A5 B5 A4]
time 178ms: Time slice expired; preempting process B7 with 7ms remaining [Q A9 A0 B0 B2 A1 A7 A8 A2 B9 B6 A6 A5 B5 A4]
time 182ms: Process A9 started using the CPU for 360ms burst [Q A0 B0 B2 A1 A7 A8 A2 B9 B6 A6 A5 B5 A4 B7]
time 225ms: Process B8 arrived; added to ready queue [Q A0 B0 B2 A1 A7 A8 A2 B9 B6 A6 A5 B5 A4 B7 B8]
time 246ms: Time slice expired; preempting process A9 with 296ms remaining [Q A0 B0 B2 A1 A7 A8 A2 B9 B6 A6 A5 B5 A4 B7 B8]
time 250ms: Process A0 started using the CPU for 196ms burst [Q B0 B2 A1 A7 A8 A2 B9 B6 A6 A5 B5 A4 B7 B8 A9]
time 263ms: Process B1 completed I/O; added to ready queue [Q B0 B2 A1 A7 A8 A2 B9 B6 A6 A5 B5 A4 B7 B8 A9 B1]
time 271ms: Process B3 arrived; added to ready queue [Q B0 B2 A1 A7 A8 A2 B9 B6 A6 A5 B5 A4 B7 B8 A9 B1 B3]
time 314ms: Time slice expired; preempting process A0 with 132ms remaining [Q B0 B2 A1 A7 A8 A2 B9 B6 A6 A5 B5 A4 B7 B8 A9 B1 B3]
time 318ms: Process B0 started using the CPU for 216ms burst [Q B2 A1 A7 A8 A2 B9 B6 A6 A5 B5 A4 B7 B8 A9 B1 B3 A0]
time 324ms: Process A3 arrived; added to ready queue [Q B2 A1 A7 A8 A2 B9 B6 A6 A5 B5 A4 B7 B8 A9 B1 B3 A0 A3]
time 382ms: Time slice expired; preempting process B0 with 152ms remaining [Q B2 A1 A7 A8 A2 B9 B6 A6 A5 B5 A4 B7 B8 A9 B1 B3 A0 A3]
time 386ms: Process B2 started using the CPU for 122ms burst [Q A1 A7 A8 A2 B9 B6 A6 A5 B5 A4 B7 B8 A9 B1 B3 A0 A3 B0]
time 450ms: Time slice expired; preempting process B2 with 58ms remaining [Q A1 A7 A8 A2 B9 B6 A6 A5 B5 A4 B7 B8 A9 B1 B3 A0 A3 B0]
time 454ms: Process A1 started using the CPU for 632ms burst [Q A7 A8 A2 B9 B6 A6 A5 B5 A4 B7 B8 A9 B1 B3 A0 A3 B0 B2]
time 518ms: Time slice expired; preempting process A1 with 568ms remaining [Q A7 A8 A2 B9 B6 A6 A5 B5 A4 B7 B8 A9 B1 B3 A0 A3 B0 B2]
time 522ms: Process A7 started using the CPU for 84ms burst [Q A8 A2 B9 B6 A6 A5 B5 A4 B7 B8 A9 B1 B3 A0 A3 B0 B2 A1]
time 586ms: Time slice expired; preempting process A7 with 20ms remaining [Q A8 A2 B9 B6 A6 A5 B5 A4 B7 B8 A9 B1 B3 A0 A3 B0 B2 A1]
time 590ms: Process A8 started using the CPU for 420ms burst [Q A2 B9 B6 A6 A5 B5 A4 B7 B8 A9 B1 B3 A0 A3 B0 B2 A1 A7]
time 654ms: Time slice expired; preempting process A8 with 356ms remaining [Q A2 B9 B6 A6 A5 B5 A4 B7 B8 A9 B1 B3 A0 A3 B0 B2 A1 A7]
time 658ms: Process A2 started using the CPU for 28ms burst [Q B9 B6 A6 A5 B5 A4 B7 B8 A9 B1 B3 A0 A3 B0 B2 A1 A7 A8]
time 686ms: Process A2 completed a CPU burst; 29 bursts to go [Q B9 B6 A6 A5 B5 A4 B7 B8 A9 B1 B3 A0 A3 B0 B2 A1 A7 A8]
time 686ms: Process A2 switching out of CPU; blocking on I/O until time 701ms [Q B9 B6 A6 A5 B5 A4 B7 B8 A9 B1 B3 A0 A3 B0 B2 A1 A7 A8]
time 689ms: Process B9 started using the CPU for 22ms burst [Q B6 A6 A5 B5 A4 B7 B8 A9 B1 B3 A0 A3 B0 B2 A1 A7 A8]
time 701ms: Process A2 completed I/O; added to ready queue [Q B6 A6 A5 B5 A4 B7 B8 A9 B1 B3 A0 A3 B0 B2 A1 A7 A8 A2]
time 711ms: Process B9 completed a CPU burst; 10 bursts to go [Q B6 A6 A5 B5 A4 B7 B8 A9 B1 B3 A0 A3 B0 B2 A1 A7 A8 A2]
time 711ms: Process B9 switching out of CPU; blocking on I/O until time 1321ms [Q B6 A6 A5 B5 A4 B7 B8 A9 B1 B3 A0 A3 B0 B2 A1 A7 A8 A2]
time 714ms: Process B6 started using the CPU for 113ms burst [Q A6 A5 B5 A4 B7 B8 A9 B1 B3 A0 A3 B0 B2 A1 A7 A8 A2]
time 778ms: Time slice expired; preempting process B6 with 49ms remaining [Q A6 A5 B5 A4 B7 B8 A9 B1 B3 A0 A3 B0 B2 A1 A7 A8 A2]
time 782ms: Process A6 started using the CPU for remaining 216ms of 280ms burst [Q A5 B5 A4 B7 B8 A9 B1 B3 A0 A3 B0 B2 A1 A7 A8 A2 B6]
time 846ms: Time slice expired; preempting process A6 with 152ms remaining [Q A5 B5 A4 B7 B8 A9 B1 B3 A0 A3 B0 B2 A1 A7 A8 A2 B6]
time 850ms: Process A5 started using the CPU for 196ms burst [Q B5 A4 B7 B8 A9 B1 B3 A0 A3 B0 B2 A1 A7 A8 A2 B6 A6]
time 914ms: Time slice expired; preempting process A5 with 132ms remaining [Q B5 A4 B7 B8 A9 B1 B3 A0 A3 B0 B2 A1 A7 A8 A2 B6 A6]
time 918ms: Process B5 started using the CPU for 20ms burst [Q A4 B7 B8 A9 B1 B3 A0 A3 B0 B2 A1 A7 A8 A2 B6 A6 A5]
time 938ms: Process B5 completed a CPU burst; 29 bursts to go [Q A4 B7 B8 A9 B1 B3 A0 A3 B0 B2 A1 A7 A8 A2 B6 A6 A5]
time 938ms: Process B5 switching out of CPU; blocking on I/O until time 1188ms [Q A4 B7 B8 A9 B1 B3 A0 A3 B0 B2 A1 A7 A8 A2 B6 A6 A5]
time 941ms: Process A4 started using the CPU for 300ms burst [Q B7 B8 A9 B1 B3 A0 A3 B0 B2 A1 A7 A8 A2 B6 A6 A5]
time 982ms: Process B4 completed I/O; added to ready queue [Q B7 B8 A9 B1 B3 A0 A3 B0 B2 A1 A7 A8 A2 B6 A6 A5 B4]
time 1005ms: Time slice expired; preempting process A4 with 236ms remaining [Q B7 B8 A9 B1 B3 A0 A3 B0 B2 A1 A7 A8 A2 B6 A6 A5 B4]
time 1009ms: Process B7 started using the CPU for remaining 7ms of 71ms burst [Q B8 A9 B1 B3 A0 A3 B0 B2 A1 A7 A8 A2 B6 A6 A5 B4 A4]
time 1016ms: Process B7 completed a CPU burst; 25 bursts to go [Q B8 A9 B1 B3 A0 A3 B0 B2 A1 A7 A8 A2 B6 A6 A5 B4 A4]
time 1016ms: Process B7 switching out of CPU; blocking on I/O until time 4066ms [Q B8 A9 B1 B3 A0 A3 B0 B2 A1 A7 A8 A2 B6 A6 A5 B4 A4]
time 1019ms: Process B8 started using the CPU for 308ms burst [Q A9 B1 B3 A0 A3 B0 B2 A1 A7 A8 A2 B6 A6 A5 B4 A4]
time 1083ms: Time slice expired; preempting process B8 with 244ms remaining [Q A9 B1 B3 A0 A3 B0 B2 A1 A7 A8 A2 B6 A6 A5 B4 A4]
time 1087ms: Process A9 started using the CPU for remaining 296ms of 360ms burst [Q B1 B3 A0 A3 B0 B2 A1 A7 A8 A2 B6 A6 A5 B4 A4 B8]
time 1151ms: Time slice expired; preempting process A9 with 232ms remaining [Q B1 B3 A0 A3 B0 B2 A1 A7 A8 A2 B6 A6 A5 B4 A4 B8]
time 1155ms: Process B1 started using the CPU for 3004ms burst [Q B3 A0 A3 B0 B2 A1 A7 A8 A2 B6 A6 A5 B4 A4 B8 A9]
time 1188ms: Process B5 completed I/O; added to ready queue [Q B3 A0 A3 B0 B2 A1 A7 A8 A2 B6 A6 A5 B4 A4 B8 A9 B5]
time 1219ms: Time slice expired; preempting process B1 with 2940ms remaining [Q B3 A0 A3 B0 B2 A1 A7 A8 A2 B6 A6 A5 B4 A4 B8 A9 B5]
time 1223ms: Process B3 started using the CPU for 51ms burst [Q A0 A3 B0 B2 A1 A7 A8 A2 B6 A6 A5 B4 A4 B8 A9 B5 B1]
time 1274ms: Process B3 completed a CPU burst; 21 bursts to go [Q A0 A3 B0 B2 A1 A7 A8 A2 B6 A6 A5 B4 A4 B8 A9 B5 B1]
time 1274ms: Process B3 switching out of CPU; blocking on I/O until time 3612ms [Q A0 A3 B0 B2 A1 A7 A8 A2 B6 A6 A5 B4 A4 B8 A9 B5 B1]
time 1277ms: Process A0 started using the CPU for remaining 132ms of 196ms burst [Q A3 B0 B2 A1 A7 A8 A2 B6 A6 A5 B4 A4 B8 A9 B5 B1]
time 1321ms: Process B9 completed I/O; added to ready queue [Q A3 B0 B2 A1 A7 A8 A2 B6 A6 A5 B4 A4 B8 A9 B5 B1 B9]
time 1341ms: Time slice expired; preempting process A0 with 68ms remaining [Q A3 B0 B2 A1 A7 A8 A2 B6 A6 A5 B4 A4 B8 A9 B5 B1 B9]
time 1345ms: Process A3 started using the CPU for 96ms burst [Q B0 B2 A1 A7 A8 A2 B6 A6 A5 B4 A4 B8 A9 B5 B1 B9 A0]
time 1409ms: Time slice expired; preempting process A3 with 32ms remaining [Q B0 B2 A1 A7 A8 A2 B6 A6 A5 B4 A4 B8 A9 B5 B1 B9 A0]
time 1413ms: Process B0 started using the CPU for remaining 152ms of 216ms burst [Q B2 A1 A7 A8 A2 B6 A6 A5 B4 A4 B8 A9 B5 B1 B9 A0 A3]
time 1477ms: Time slice expired; preempting process B0 with 88ms remaining [Q B2 A1 A7 A8 A2 B6 A6 A5 B4 A4 B8 A9 B5 B1 B9 A0 A3]
time 1481ms: Process B2 started using the CPU for remaining 58ms of 122ms burst [Q A1 A7 A8 A2 B6 A6 A5 B4 A4 B8 A9 B5 B1 B9 A0 A3 B0]
time 1539ms: Process B2 completed a CPU burst; 14 bursts to go [Q A1 A7 A8 A2 B6 A6 A5 B4 A4 B8 A9 B5 B1 B9 A0 A3 B0]
time 1539ms: Process B2 switching out of CPU; blocking on I/O until time 2061ms [Q A1 A7 A8 A2 B6 A6 A5 B4 A4 B8 A9 B5 B1 B9 A0 A3 B0]
time 1542ms: Process A1 started using the CPU for remaining 568ms of 632ms burst [Q A7 A8 A2 B6 A6 A5 B4 A4 B8 A9 B5 B1 B9 A0 A3 B0]
time 1606ms: Time slice expired; preempting process A1 with 504ms remaining [Q A7 A8 A2 B6 A6 A5 B4 A4 B8 A9 B5 B1 B9 A0 A3 B0]
time 1610ms: Process A7 started using the CPU for remaining 20ms of 84ms burst [Q A8 A2 B6 A6 A5 B4 A4 B8 A9 B5 B1 B9 A0 A3 B0 A1]
time 1630ms: Process A7 completed a CPU burst; 18 bursts to go [Q A8 A2 B6 A6 A5 B4 A4 B8 A9 B5 B1 B9 A0 A3 B0 A1]
time 1630ms: Process A7 switching out of CPU; blocking on I/O until time 1681ms [Q A8 A2 B6 A6 A5 B4 A4 B8 A9 B5 B1 B9 A0 A3 B0 A1]
time 1633ms: Process A8 started using the CPU for remaining 356ms of 420ms burst [Q A2 B6 A6 A5 B4 A4 B8 A9 B5 B1 B9 A0 A3 B0 A1]
time 1681ms: Process A7 completed I/O; added to ready queue [Q A2 B6 A6 A5 B4 A4 B8 A9 B5 B1 B9 A0 A3 B0 A1 A7]
time 1697ms: Time slice expired; preempting process A8 with 292ms remaining [Q A2 B6 A6 A5 B4 A4 B8 A9 B5 B1 B9 A0 A3 B0 A1 A7]
time 1701ms: Process A2 started using the CPU for 444ms burst [Q B6 A6 A5 B4 A4 B8 A9 B5 B1 B9 A0 A3 B0 A1 A7 A8]
time 1765ms: Time slice expired; preempting process A2 with 380ms remaining [Q B6 A6 A5 B4 A4 B8 A9 B5 B1 B9 A0 A3 B0 A1 A7 A8]
time 1769ms: Process B6 started using the CPU for remaining 49ms of 113ms burst [Q A6 A5 B4 A4 B8 A9 B5 B1 B9 A0 A3 B0 A1 A7 A8 A2]
time 1818ms: Process B6 completed a CPU burst; 4 bursts to go [Q A6 A5 B4 A4 B8 A9 B5 B1 B9 A0 A3 B0 A1 A7 A8 A2]
time 1818ms: Process B6 switching out of CPU; blocking on I/O until time 5044ms [Q A6 A5 B4 A4 B8 A9 B5 B1 B9 A0 A3 B0 A1 A7 A8 A2]
time 1821ms: Process A6 started using the CPU for remaining 152ms of 280ms burst [Q A5 B4 A4 B8 A9 B5 B1 B9 A0 A3 B0 A1 A7 A8 A2]
time 1885ms: Time slice expired; preempting process A6 with 88ms remaining [Q A5 B4 A4 B8 A9 B5 B1 B9 A0 A3 B0 A1 A7 A8 A2]
time 1889ms: Process A5 started using the CPU for remaining 132ms of 196ms burst [Q B4 A4 B8 A9 B5 B1 B9 A0 A3 B0 A1 A7 A8 A2 A6]
time 1953ms: Time slice expired; preempting process A5 with 68ms remaining [Q B4 A4 B8 A9 B5 B1 B9 A0 A3 B0 A1 A7 A8 A2 A6]
time 1957ms: Process B4 started using the CPU for 3ms burst [Q A4 B8 A9 B5 B1 B9 A0 A3 B0 A1 A7 A8 A2 A6 A5]
time 1960ms: Process B4 completed a CPU burst; 14 bursts to go [Q A4 B8 A9 B5 B1 B9 A0 A3 B0 A1 A7 A8 A2 A6 A5]
time 1960ms: Process B4 switching out of CPU; blocking on I/O until time 3058ms [Q A4 B8 A9 B5 B1 B9 A0 A3 B0 A1 A7 A8 A2 A6 A5]
time 1963ms: Process A4 started using the CPU for remaining 236ms of 300ms burst [Q B8 A9 B5 B1 B9 A0 A3 B0 A1 A7 A8 A2 A6 A5]
time 2027ms: Time slice expired; preempting process A4 with 172ms remaining [Q B8 A9 B5 B1 B9 A0 A3 B0 A1 A7 A8 A2 A6 A5]
time 2031ms: Process B8 started using the CPU for remaining 244ms of 308ms burst [Q A9 B5 B1 B9 A0 A3 B0 A1 A7 A8 A2 A6 A5 A4]
time 2061ms: Process B2 completed I/O; added to ready queue [Q A9 B5 B1 B9 A0 A3 B0 A1 A7 A8 A2 A6 A5 A4 B2]
time 2095ms: Time slice expired; preempting process B8 with 180ms remaining [Q A9 B5 B1 B9 A0 A3 B0 A1 A7 A8 A2 A6 A5 A4 B2]
time 2099ms: Process A9 started using the CPU for remaining 232ms of 360ms burst [Q B5 B1 B9 A0 A3 B0 A1 A7 A8 A2 A6 A5 A4 B2 B8]
time 2163ms: Time slice expired; preempting process A9 with 168ms remaining [Q B5 B1 B9 A0 A3 B0 A1 A7 A8 A2 A6 A5 A4 B2 B8]
time 2167ms: Process B5 started using the CPU for 85ms burst [Q B1 B9 A0 A3 B0 A1 A7 A8 A2 A6 A5 A4 B2 B8 A9]
time 2231ms: Time slice expired; preempting process B5 with 21ms remaining [Q B1 B9 A0 A3 B0 A1 A7 A8 A2 A6 A5 A4 B2 B8 A9]
time 2235ms: Process B1 started using the CPU for remaining 2940ms of 3004ms burst [Q B9 A0 A3 B0 A1 A7 A8 A2 A6 A5 A4 B2 B8 A9 B5]
time 2299ms: Time slice expired; preempting process B1 with 2876ms remaining [Q B9 A0 A3 B0 A1 A7 A8 A2 A6 A5 A4 B2 B8 A9 B5]
time 2303ms: Process B9 started using the CPU for 142ms burst [Q A0 A3 B0 A1 A7 A8 A2 A6 A5 A4 B2 B8 A9 B5 B1]
time 2367ms: Time slice expired; preempting process B9 with 78ms remaining [Q A0 A3 B0 A1 A7 A8 A2 A6 A5 A4 B2 B8 A9 B5 B1]
time 2371ms: Process A0 started using the CPU for remaining 68ms of 196ms burst [Q A3 B0 A1 A7 A8 A2 A6 A5 A4 B2 B8 A9 B5 B1 B9]
time 2435ms: Time slice expired; preempting process A0 with 4ms remaining [Q A3 B0 A1 A7 A8 A2 A6 A5 A4 B2 B8 A9 B5 B1 B9]
time 2439ms: Process A3 started using the CPU for remaining 32ms of 96ms burst [Q B0 A1 A7 A8 A2 A6 A5 A4 B2 B8 A9 B5 B1 B9 A0]
time 2471ms: Process A3 completed a CPU burst; 25 bursts to go [Q B0 A1 A7 A8 A2 A6 A5 A4 B2 B8 A9 B5 B1 B9 A0]
time 2471ms: Process A3 switching out of CPU; blocking on I/O until time 2843ms [Q B0 A1 A7 A8 A2 A6 A5 A4 B2 B8 A9 B5 B1 B9 A0]
time 2474ms: Process B0 started using the CPU for remaining 88ms of 216ms burst [Q A1 A7 A8 A2 A6 A5 A4 B2 B8 A9 B5 B1 B9 A0]
time 2538ms: Time slice expired; preempting process B0 with 24ms remaining [Q A1 A7 A8 A2 A6 A5 A4 B2 B8 A9 B5 B1 B9 A0]
time 2542ms: Process A1 started using the CPU for remaining 504ms of 632ms burst [Q A7 A8 A2 A6 A5 A4 B2 B8 A9 B5 B1 B9 A0 B0]
time 2606ms: Time slice expired; preempting process A1 with 440ms remaining [Q A7 A8 A2 A6 A5 A4 B2 B8 A9 B5 B1 B9 A0 B0]
time 2610ms: Process A7 started using the CPU for 768ms burst [Q A8 A2 A6 A5 A4 B2 B8 A9 B5 B1 B9 A0 B0 A1]
time 2674ms: Time slice expired; preempting process A7 with 704ms remaining [Q A8 A2 A6 A5 A4 B2 B8 A9 B5 B1 B9 A0 B0 A1]
time 2678ms: Process A8 started using the CPU for remaining 292ms of 420ms burst [Q A2 A6 A5 A4 B2 B8 A9 B5 B1 B9 A0 B0 A1 A7]
time 2742ms: Time slice expired; preempting process A8 with 228ms remaining [Q A2 A6 A5 A4 B2 B8 A9 B5 B1 B9 A0 B0 A1 A7]
time 2746ms: Process A2 started using the CPU for remaining 380ms of 444ms burst [Q A6 A5 A4 B2 B8 A9 B5 B1 B9 A0 B0 A1 A7 A8]
time 2810ms: Time slice expired; preempting process A2 with 316ms remaining [Q A6 A5 A4 B2 B8 A9 B5 B1 B9 A0 B0 A1 A7 A8]
time 2814ms: Process A6 started using the CPU for remaining 88ms of 280ms burst [Q A5 A4 B2 B8 A9 B5 B1 B9 A0 B0 A1 A7 A8 A2]
time 2843ms: Process A3 completed I/O; added to ready queue [Q A5 A4 B2 B8 A9 B5 B1 B9 A0 B0 A1 A7 A8 A2 A3]
time 2878ms: Time slice expired; preempting process A6 with 24ms remaining [Q A5 A4 B2 B8 A9 B5 B1 B9 A0 B0 A1 A7 A8 A2 A3]
time 2882ms: Process A5 started using the CPU for remaining 68ms of 196ms burst [Q A4 B2 B8 A9 B5 B1 B9 A0 B0 A1 A7 A8 A2 A3 A6]
time 2946ms: Time slice expired; preempting process A5 with 4ms remaining [Q A4 B2 B8 A9 B5 B1 B9 A0 B0 A1 A7 A8 A2 A3 A6]
time 2950ms: Process A4 started using the CPU for remaining 172ms of 300ms burst [Q B2 B8 A9 B5 B1 B9 A0 B0 A1 A7 A8 A2 A3 A6 A5]
time 3014ms: Time slice expired; preempting process A4 with 108ms remaining [Q B2 B8 A9 B5 B1 B9 A0 B0 A1 A7 A8 A2 A3 A6 A5]
time 3018ms: Process B2 started using the CPU for 183ms burst [Q B8 A9 B5 B1 B9 A0 B0 A1 A7 A8 A2 A3 A6 A5 A4]
time 3058ms: Process B4 completed I/O; added to ready queue [Q B8 A9 B5 B1 B9 A0 B0 A1 A7 A8 A2 A3 A6 A5 A4 B4]
time 3082ms: Time slice expired; preempting process B2 with 119ms remaining [Q B8 A9 B5 B1 B9 A0 B0 A1 A7 A8 A2 A3 A6 A5 A4 B4]
time 3086ms: Process B8 started using the CPU for remaining 180ms of 308ms burst [Q A9 B5 B1 B9 A0 B0 A1 A7 A8 A2 A3 A6 A5 A4 B4 B2]
time 3150ms: Time slice expired; preempting process B8 with 116ms remaining [Q A9 B5 B1 B9 A0 B0 A1 A7 A8 A2 A3 A6 A5 A4 B4 B2]
time 3154ms: Process A9 started using the CPU for remaining 168ms of 360ms burst [Q B5 B1 B9 A0 B0 A1 A7 A8 A2 A3 A6 A5 A4 B4 B2 B8]
time 3218ms: Time slice expired; preempting process A9 with 104ms remaining [Q B5 B1 B9 A0 B0 A1 A7 A8 A2 A3 A6 A5 A4 B4 B2 B8]
time 3222ms: Process B5 started using the CPU for remaining 21ms of 85ms burst [Q B1 B9 A0 B0 A1 A7 A8 A2 A3 A6 A5 A4 B4 B2 B8 A9]
time 3243ms: Process B5 completed a CPU burst; 28 bursts to go [Q B1 B9 A0 B0 A1 A7 A8 A2 A3 A6 A5 A4 B4 B2 B8 A9]
time 3243ms: Process B5 switching out of CPU; blocking on I/O until time 3485ms [Q B1 B9 A0 B0 A1 A7 A8 A2 A3 A6 A5 A4 B4 B2 B8 A9]
time 3246ms: Process B1 started using the CPU for remaining 2876ms of 3004ms burst [Q B9 A0 B0 A1 A7 A8 A2 A3 A6 A5 A4 B4 B2 B8 A9]
time 3310ms: Time slice expired; preempting process B1 with 2812ms remaining [Q B9 A0 B0 A1 A7 A8 A2 A3 A6 A5 A4 B4 B2 B8 A9]
time 3314ms: Process B9 started using the CPU for remaining 78ms of 142ms burst [Q A0 B0 A1 A7 A8 A2 A3 A6 A5 A4 B4 B2 B8 A9 B1]
time 3378ms: Time slice expired; preempting process B9 with 14ms remaining [Q A0 B0 A1 A7 A8 A2 A3 A6 A5 A4 B4 B2 B8 A9 B1]
time 3382ms: Process A0 started using the CPU for remaining 4ms of 196ms burst [Q B0 A1 A7 A8 A2 A3 A6 A5 A4 B4 B2 B8 A9 B1 B9]
time 3386ms: Process A0 completed a CPU burst; 29 bursts to go [Q B0 A1 A7 A8 A2 A3 A6 A5 A4 B4 B2 B8 A9 B1 B9]
time 3386ms: Process A0 switching out of CPU; blocking on I/O until time 3467ms [Q B0 A1 A7 A8 A2 A3 A6 A5 A4 B4 B2 B8 A9 B1 B9]
time 3389ms: Process B0 started using the CPU for remaining 24ms of 216ms burst [Q A1 A7 A8 A2 A3 A6 A5 A4 B4 B2 B8 A9 B1 B9]
time 3413ms: Process B0 completed a CPU burst; 18 bursts to go [Q A1 A7 A8 A2 A3 A6 A5 A4 B4 B2 B8 A9 B1 B9]
time 3413ms: Process B0 switching out of CPU; blocking on I/O until time 3564ms [Q A1 A7 A8 A2 A3 A6 A5 A4 B4 B2 B8 A9 B1 B9]
time 3416ms: Process A1 started using the CPU for remaining 440ms of 632ms burst [Q A7 A8 A2 A3 A6 A5 A4 B4 B2 B8 A9 B1 B9]
time 3467ms: Process A0 completed I/O; added to ready queue [Q A7 A8 A2 A3 A6 A5 A4 B4 B2 B8 A9 B1 B9 A0]
time 3480ms: Time slice expired; preempting process A1 with 376ms remaining [Q A7 A8 A2 A3 A6 A5 A4 B4 B2 B8 A9 B1 B9 A0]
time 3484ms: Process A7 started using the CPU for remaining 704ms of 768ms burst [Q A8 A2 A3 A6 A5 A4 B4 B2 B8 A9 B1 B9 A0 A1]
time 3485ms: Process B5 completed I/O; added to ready queue [Q A8 A2 A3 A6 A5 A4 B4 B2 B8 A9 B1 B9 A0 A1 B5]
time 3548ms: Time slice expired; preempting process A7 with 640ms remaining [Q A8 A2 A3 A6 A5 A4 B4 B2 B8 A9 B1 B9 A0 A1 B5]
time 3552ms: Process A8 started using the CPU for remaining 228ms of 420ms burst [Q A2 A3 A6 A5 A4 B4 B2 B8 A9 B1 B9 A0 A1 B5 A7]
time 3564ms: Process B0 completed I/O; added to ready queue [Q A2 A3 A6 A5 A4 B4 B2 B8 A9 B1 B9 A0 A1 B5 A7 B0]
time 3612ms: Process B3 completed I/O; added to ready queue [Q A2 A3 A6 A5 A4 B4 B2 B8 A9 B1 B9 A0 A1 B5 A7 B0 B3]
time 3616ms: Time slice expired; preempting process A8 with 164ms remaining [Q A2 A3 A6 A5 A4 B4 B2 B8 A9 B1 B9 A0 A1 B5 A7 B0 B3]
time 3620ms: Process A2 started using the CPU for remaining 316ms of 444ms burst [Q A3 A6 A5 A4 B4 B2 B8 A9 B1 B9 A0 A1 B5 A7 B0 B3 A8]
time 3684ms: Time slice expired; preempting process A2 with 252ms remaining [Q A3 A6 A5 A4 B4 B2 B8 A9 B1 B9 A0 A1 B5 A7 B0 B3 A8]
time 3688ms: Process A3 started using the CPU for 308ms burst [Q A6 A5 A4 B4 B2 B8 A9 B1 B9 A0 A1 B5 A7 B0 B3 A8 A2]
time 3752ms: Time slice expired; preempting process A3 with 244ms remaining [Q A6 A5 A4 B4 B2 B8 A9 B1 B9 A0 A1 B5 A7 B0 B3 A8 A2]
time 3756ms: Process A6 started using the CPU for remaining 24ms of 280ms burst [Q A5 A4 B4 B2 B8 A9 B1 B9 A0 A1 B5 A7 B0 B3 A8 A2 A3]
time 3780ms: Process A6 completed a CPU burst; 17 bursts to go [Q A5 A4 B4 B2 B8 A9 B1 B9 A0 A1 B5 A7 B0 B3 A8 A2 A3]
time 3780ms: Process A6 switching out of CPU; blocking on I/O until time 3854ms [Q A5 A4 B4 B2 B8 A9 B1 B9 A0 A1 B5 A7 B0 B3 A8 A2 A3]
time 3783ms: Process A5 started using the CPU for remaining 4ms of 196ms burst [Q A4 B4 B2 B8 A9 B1 B9 A0 A1 B5 A7 B0 B3 A8 A2 A3]
time 3787ms: Process A5 completed a CPU burst; 4 bursts to go [Q A4 B4 B2 B8 A9 B1 B9 A0 A1 B5 A7 B0 B3 A8 A2 A3]
time 3787ms: Process A5 switching out of CPU; blocking on I/O until time 3806ms [Q A4 B4 B2 B8 A9 B1 B9 A0 A1 B5 A7 B0 B3 A8 A2 A3]
time 3790ms: Process A4 started using the CPU for remaining 108ms of 300ms burst [Q B4 B2 B8 A9 B1 B9 A0 A1 B5 A7 B0 B3 A8 A2 A3]
time 3806ms: Process A5 completed I/O; added to ready queue [Q B4 B2 B8 A9 B1 B9 A0 A1 B5 A7 B0 B3 A8 A2 A3 A5]
time 3854ms: Time slice expired; preempting process A4 with 44ms remaining [Q B4 B2 B8 A9 B1 B9 A0 A1 B5 A7 B0 B3 A8 A2 A3 A5]
time 3854ms: Process A6 completed I/O; added to ready queue [Q B4 B2 B8 A9 B1 B9 A0 A1 B5 A7 B0 B3 A8 A2 A3 A5 A4 A6]
time 3858ms: Process B4 started using the CPU for 285ms burst [Q B2 B8 A9 B1 B9 A0 A1 B5 A7 B0 B3 A8 A2 A3 A5 A4 A6]
time 3922ms: Time slice expired; preempting process B4 with 221ms remaining [Q B2 B8 A9 B1 B9 A0 A1 B5 A7 B0 B3 A8 A2 A3 A5 A4 A6]
time 3926ms: Process B2 started using the CPU for remaining 119ms of 183ms burst [Q B8 A9 B1 B9 A0 A1 B5 A7 B0 B3 A8 A2 A3 A5 A4 A6 B4]
time 3990ms: Time slice expired; preempting process B2 with 55ms remaining [Q B8 A9 B1 B9 A0 A1 B5 A7 B0 B3 A8 A2 A3 A5 A4 A6 B4]
time 3994ms: Process B8 started using the CPU for remaining 116ms of 308ms burst [Q A9 B1 B9 A0 A1 B5 A7 B0 B3 A8 A2 A3 A5 A4 A6 B4 B2]
time 4058ms: Time slice expired; preempting process B8 with 52ms remaining [Q A9 B1 B9 A0 A1 B5 A7 B0 B3 A8 A2 A3 A5 A4 A6 B4 B2]
time 4062ms: Process A9 started using the CPU for remaining 104ms of 360ms burst [Q B1 B9 A0 A1 B5 A7 B0 B3 A8 A2 A3 A5 A4 A6 B4 B2 B8]
time 4066ms: Process B7 completed I/O; added to ready queue [Q B1 B9 A0 A1 B5 A7 B0 B3 A8 A2 A3 A5 A4 A6 B4 B2 B8 B7]
time 4126ms: Time slice expired; preempting process A9 with 40ms remaining [Q B1 B9 A0 A1 B5 A7 B0 B3 A8 A2 A3 A5 A4 A6 B4 B2 B8 B7]
time 4130ms: Process B1 started using the CPU for remaining 2812ms of 3004ms burst [Q B9 A0 A1 B5 A7 B0 B3 A8 A2 A3 A5 A4 A6 B4 B2 B8 B7 A9]
time 4194ms: Time slice expired; preempting process B1 with 2748ms remaining [Q B9 A0 A1 B5 A7 B0 B3 A8 A2 A3 A5 A4 A6 B4 B2 B8 B7 A9]
time 4198ms: Process B9 started using the CPU for remaining 14ms of 142ms burst [Q A0 A1 B5 A7 B0 B3 A8 A2 A3 A5 A4 A6 B4 B2 B8 B7 A9 B1]
time 4212ms: Process B9 completed a CPU burst; 9 bursts to go [Q A0 A1 B5 A7 B0 B3 A8 A2 A3 A5 A4 A6 B4 B2 B8 B7 A9 B1]
time 4212ms: Process B9 switching out of CPU; blocking on I/O until time 4286ms [Q A0 A1 B5 A7 B0 B3 A8 A2 A3 A5 A4 A6 B4 B2 B8 B7 A9 B1]
time 4215ms: Process A0 started using the CPU for 1096ms burst [Q A1 B5 A7 B0 B3 A8 A2 A3 A5 A4 A6 B4 B2 B8 B7 A9 B1]
time 4279ms: Time slice expired; preempting process A0 with 1032ms remaining [Q A1 B5 A7 B0 B3 A8 A2 A3 A5 A4 A6 B4 B2 B8 B7 A9 B1]
time 4283ms: Process A1 started using the CPU for remaining 376ms of 632ms burst [Q B5 A7 B0 B3 A8 A2 A3 A5 A4 A6 B4 B2 B8 B7 A9 B1 A0]
time 4286ms: Process B9 completed I/O; added to ready queue [Q B5 A7 B0 B3 A8 A2 A3 A5 A4 A6 B4 B2 B8 B7 A9 B1 A0 B9]
time 4347ms: Time slice expired; preempting process A1 with 312ms remaining [Q B5 A7 B0 B3 A8 A2 A3 A5 A4 A6 B4 B2 B8 B7 A9 B1 A0 B9]
time 4351ms: Process B5 started using the CPU for 20ms burst [Q A7 B0 B3 A8 A2 A3 A5 A4 A6 B4 B2 B8 B7 A9 B1 A0 B9 A1]
time 4371ms: Process B5 completed a CPU burst; 27 bursts to go [Q A7 B0 B3 A8 A2 A3 A5 A4 A6 B4 B2 B8 B7 A9 B1 A0 B9 A1]
time 4371ms: Process B5 switching out of CPU; blocking on I/O until time 4797ms [Q A7 B0 B3 A8 A2 A3 A5 A4 A6 B4 B2 B8 B7 A9 B1 A0 B9 A1]
time 4374ms: Process A7 started using the CPU for remaining 640ms of 768ms burst [Q B0 B3 A8 A2 A3 A5 A4 A6 B4 B2 B8 B7 A9 B1 A0 B9 A1]
time 4438ms: Time slice expired; preempting process A7 with 576ms remaining [Q B0 B3 A8 A2 A3 A5 A4 A6 B4 B2 B8 B7 A9 B1 A0 B9 A1]
time 4442ms: Process B0 started using the CPU for 1264ms burst [Q B3 A8 A2 A3 A5 A4 A6 B4 B2 B8 B7 A9 B1 A0 B9 A1 A7]
time 4506ms: Time slice expired; preempting process B0 with 1200ms remaining [Q B3 A8 A2 A3 A5 A4 A6 B4 B2 B8 B7 A9 B1 A0 B9 A1 A7]
time 4510ms: Process B3 started using the CPU for 129ms burst [Q A8 A2 A3 A5 A4 A6 B4 B2 B8 B7 A9 B1 A0 B9 A1 A7 B0]
time 4574ms: Time slice expired; preempting process B3 with 65ms remaining [Q A8 A2 A3 A5 A4 A6 B4 B2 B8 B7 A9 B1 A0 B9 A1 A7 B0]
time 4578ms: Process A8 started using the CPU for remaining 164ms of 420ms burst [Q A2 A3 A5 A4 A6 B4 B2 B8 B7 A9 B1 A0 B9 A1 A7 B0 B3]
time 4642ms: Time slice expired; preempting process A8 with 100ms remaining [Q A2 A3 A5 A4 A6 B4 B2 B8 B7 A9 B1 A0 B9 A1 A7 B0 B3]
time 4646ms: Process A2 started using the CPU for remaining 252ms of 444ms burst [Q A3 A5 A4 A6 B4 B2 B8 B7 A9 B1 A0 B9 A1 A7 B0 B3 A8]
time 4710ms: Time slice expired; preempting process A2 with 188ms remaining [Q A3 A5 A4 A6 B4 B2 B8 B7 A9 B1 A0 B9 A1 A7 B0 B3 A8]
time 4714ms: Process A3 started using the CPU for remaining 244ms of 308ms burst [Q A5 A4 A6 B4 B2 B8 B7 A9 B1 A0 B9 A1 A7 B0 B3 A8 A2]
time 4778ms: Time slice expired; preempting process A3 with 180ms remaining [Q A5 A4 A6 B4 B2 B8 B7 A9 B1 A0 B9 A1 A7 B0 B3 A8 A2]
time 4782ms: Process A5 started using the CPU for 140ms burst [Q A4 A6 B4 B2 B8 B7 A9 B1 A0 B9 A1 A7 B0 B3 A8 A2 A3]
time 4797ms: Process B5 completed I/O; added to ready queue [Q A4 A6 B4 B2 B8 B7 A9 B1 A0 B9 A1 A7 B0 B3 A8 A2 A3 B5]
time 4846ms: Time slice expired; preempting process A5 with 76ms remaining [Q A4 A6 B4 B2 B8 B7 A9 B1 A0 B9 A1 A7 B0 B3 A8 A2 A3 B5]
time 4850ms: Process A4 started using the CPU for remaining 44ms of 300ms burst [Q A6 B4 B2 B8 B7 A9 B1 A0 B9 A1 A7 B0 B3 A8 A2 A3 B5 A5]
time 4894ms: Process A4 completed a CPU burst; 3 bursts to go [Q A6 B4 B2 B8 B7 A9 B1 A0 B9 A1 A7 B0 B3 A8 A2 A3 B5 A5]
time 4894ms: Process A4 switching out of CPU; blocking on I/O until time 4985ms [Q A6 B4 B2 B8 B7 A9 B1 A0 B9 A1 A7 B0 B3 A8 A2 A3 B5 A5]
time 4897ms: Process A6 started using the CPU for 100ms burst [Q B4 B2 B8 B7 A9 B1 A0 B9 A1 A7 B0 B3 A8 A2 A3 B5 A5]
time 4961ms: Time slice expired; preempting process A6 with 36ms remaining [Q B4 B2 B8 B7 A9 B1 A0 B9 A1 A7 B0 B3 A8 A2 A3 B5 A5]
time 4965ms: Process B4 started using the CPU for remaining 221ms of 285ms burst [Q B2 B8 B7 A9 B1 A0 B9 A1 A7 B0 B3 A8 A2 A3 B5 A5 A6]
time 4985ms: Process A4 completed I/O; added to ready queue [Q B2 B8 B7 A9 B1 A0 B9 A1 A7 B0 B3 A8 A2 A3 B5 A5 A6 A4]
time 5029ms: Time slice expired; preempting process B4 with 157ms remaining [Q B2 B8 B7 A9 B1 A0 B9 A1 A7 B0 B3 A8 A2 A3 B5 A5 A6 A4]
time 5033ms: Process B2 started using the CPU for remaining 55ms of 183ms burst [Q B8 B7 A9 B1 A0 B9 A1 A7 B0 B3 A8 A2 A3 B5 A5 A6 A4 B4]
time 5044ms: Process B6 completed I/O; added to ready queue [Q B8 B7 A9 B1 A0 B9 A1 A7 B0 B3 A8 A2 A3 B5 A5 A6 A4 B4 B6]
time 5088ms: Process B2 completed a CPU burst; 13 bursts to go [Q B8 B7 A9 B1 A0 B9 A1 A7 B0 B3 A8 A2 A3 B5 A5 A6 A4 B4 B6]
time 5088ms: Process B2 switching out of CPU; blocking on I/O until time 5402ms [Q B8 B7 A9 B1 A0 B9 A1 A7 B0 B3 A8 A2 A3 B5 A5 A6 A4 B4 B6]
time 5091ms: Process B8 started using the CPU for remaining 52ms of 308ms burst [Q B7 A9 B1 A0 B9 A1 A7 B0 B3 A8 A2 A3 B5 A5 A6 A4 B4 B6]
time 5143ms: Process B8 completed a CPU burst; 19 bursts to go [Q B7 A9 B1 A0 B9 A1 A7 B0 B3 A8 A2 A3 B5 A5 A6 A4 B4 B6]
time 5143ms: Process B8 switching out of CPU; blocking on I/O until time 7425ms [Q B7 A9 B1 A0 B9 A1 A7 B0 B3 A8 A2 A3 B5 A5 A6 A4 B4 B6]
time 5146ms: Process B7 started using the CPU for 20ms burst [Q A9 B1 A0 B9 A1 A7 B0 B3 A8 A2 A3 B5 A5 A6 A4 B4 B6]
time 5166ms: Process B7 completed a CPU burst; 24 bursts to go [Q A9 B1 A0 B9 A1 A7 B0 B3 A8 A2 A3 B5 A5 A6 A4 B4 B6]
time 5166ms: Process B7 switching out of CPU; blocking on I/O until time 5208ms [Q A9 B1 A0 B9 A1 A7 B0 B3 A8 A2 A3 B5 A5 A6 A4 B4 B6]
time 5169ms: Process A9 started using the CPU for remaining 40ms of 360ms burst [Q B1 A0 B9 A1 A7 B0 B3 A8 A2 A3 B5 A5 A6 A4 B4 B6]
time 5208ms: Process B7 completed I/O; added to ready queue [Q B1 A0 B9 A1 A7 B0 B3 A8 A2 A3 B5 A5 A6 A4 B4 B6 B7]
time 5209ms: Process A9 completed a CPU burst; 31 bursts to go [Q B1 A0 B9 A1 A7 B0 B3 A8 A2 A3 B5 A5 A6 A4 B4 B6 B7]
time 5209ms: Process A9 switching out of CPU; blocking on I/O until time 5251ms [Q B1 A0 B9 A1 A7 B0 B3 A8 A2 A3 B5 A5 A6 A4 B4 B6 B7]
time 5212ms: Process B1 started using the CPU for remaining 2748ms of 3004ms burst [Q A0 B9 A1 A7 B0 B3 A8 A2 A3 B5 A5 A6 A4 B4 B6 B7]
time 5251ms: Process A9 completed I/O; added to ready queue [Q A0 B9 A1 A7 B0 B3 A8 A2 A3 B5 A5 A6 A4 B4 B6 B7 A9]
time 5276ms: Time slice expired; preempting process B1 with 2684ms remaining [Q A0 B9 A1 A7 B0 B3 A8 A2 A3 B5 A5 A6 A4 B4 B6 B7 A9]
time 5280ms: Process A0 started using the CPU for remaining 1032ms of 1096ms burst [Q B9 A1 A7 B0 B3 A8 A2 A3 B5 A5 A6 A4 B4 B6 B7 A9 B1]
time 5344ms: Time slice expired; preempting process A0 with 968ms remaining [Q B9 A1 A7 B0 B3 A8 A2 A3 B5 A5 A6 A4 B4 B6 B7 A9 B1]
time 5348ms: Process B9 started using the CPU for 64ms burst [Q A1 A7 B0 B3 A8 A2 A3 B5 A5 A6 A4 B4 B6 B7 A9 B1 A0]
time 5402ms: Process B2 completed I/O; added to ready queue [Q A1 A7 B0 B3 A8 A2 A3 B5 A5 A6 A4 B4 B6 B7 A9 B1 A0 B2]
time 5412ms: Process B9 completed a CPU burst; 8 bursts to go [Q A1 A7 B0 B3 A8 A2 A3 B5 A5 A6 A4 B4 B6 B7 A9 B1 A0 B2]
time 5412ms: Process B9 switching out of CPU; blocking on I/O until time 6254ms [Q A1 A7 B0 B3 A8 A2 A3 B5 A5 A6 A4 B4 B6 B7 A9 B1 A0 B2]
time 5415ms: Process A1 started using the CPU for remaining 312ms of 632ms burst [Q A7 B0 B3 A8 A2 A3 B5 A5 A6 A4 B4 B6 B7 A9 B1 A0 B2]
time 5479ms: Time slice expired; preempting process A1 with 248ms remaining [Q A7 B0 B3 A8 A2 A3 B5 A5 A6 A4 B4 B6 B7 A9 B1 A0 B2]
time 5483ms: Process A7 started using the CPU for remaining 576ms of 768ms burst [Q B0 B3 A8 A2 A3 B5 A5 A6 A4 B4 B6 B7 A9 B1 A0 B2 A1]
time 5547ms: Time slice expired; preempting process A7 with 512ms remaining [Q B0 B3 A8 A2 A3 B5 A5 A6 A4 B4 B6 B7 A9 B1 A0 B2 A1]
time 5551ms: Process B0 started using the CPU for remaining 1200ms of 1264ms burst [Q B3 A8 A2 A3 B5 A5 A6 A4 B4 B6 B7 A9 B1 A0 B2 A1 A7]
time 5615ms: Time slice expired; preempting process B0 with 1136ms remaining [Q B3 A8 A2 A3 B5 A5 A6 A4 B4 B6 B7 A9 B1 A0 B2 A1 A7]
time 5619ms: Process B3 started using the CPU for remaining 65ms of 129ms burst [Q A8 A2 A3 B5 A5 A6 A4 B4 B6 B7 A9 B1 A0 B2 A1 A7 B0]
time 5683ms: Time slice expired; preempting process B3 with 1ms remaining [Q A8 A2 A3 B5 A5 A6 A4 B4 B6 B7 A9 B1 A0 B2 A1 A7 B0]
time 5687ms: Process A8 started using the CPU for remaining 100ms of 420ms burst [Q A2 A3 B5 A5 A6 A4 B4 B6 B7 A9 B1 A0 B2 A1 A7 B0 B3]
time 5751ms: Time slice expired; preempting process A8 with 36ms remaining [Q A2 A3 B5 A5 A6 A4 B4 B6 B7 A9 B1 A0 B2 A1 A7 B0 B3]
time 5755ms: Process A2 started using the CPU for remaining 188ms of 444ms burst [Q A3 B5 A5 A6 A4 B4 B6 B7 A9 B1 A0 B2 A1 A7 B0 B3 A8]
time 5819ms: Time slice expired; preempting process A2 with 124ms remaining [Q A3 B5 A5 A6 A4 B4 B6 B7 A9 B1 A0 B2 A1 A7 B0 B3 A8]
time 5823ms: Process A3 started using the CPU for remaining 180ms of 308ms burst [Q B5 A5 A6 A4 B4 B6 B7 A9 B1 A0 B2 A1 A7 B0 B3 A8 A2]
time 5887ms: Time slice expired; preempting process A3 with 116ms remaining [Q B5 A5 A6 A4 B4 B6 B7 A9 B1 A0 B2 A1 A7 B0 B3 A8 A2]
time 5891ms: Process B5 started using the CPU for 14ms burst [Q A5 A6 A4 B4 B6 B7 A9 B1 A0 B2 A1 A7 B0 B3 A8 A2 A3]
time 5905ms: Process B5 completed a CPU burst; 26 bursts to go [Q A5 A6 A4 B4 B6 B7 A9 B1 A0 B2 A1 A7 B0 B3 A8 A2 A3]
time 5905ms: Process B5 switching out of CPU; blocking on I/O until time 7027ms [Q A5 A6 A4 B4 B6 B7 A9 B1 A0 B2 A1 A7 B0 B3 A8 A2 A3]
time 5908ms: Process A5 started using the CPU for remaining 76ms of 140ms burst [Q A6 A4 B4 B6 B7 A9 B1 A0 B2 A1 A7 B0 B3 A8 A2 A3]
time 5972ms: Time slice expired; preempting process A5 with 12ms remaining [Q A6 A4 B4 B6 B7 A9 B1 A0 B2 A1 A7 B0 B3 A8 A2 A3]
time 5976ms: Process A6 started using the CPU for remaining 36ms of 100ms burst [Q A4 B4 B6 B7 A9 B1 A0 B2 A1 A7 B0 B3 A8 A2 A3 A5]
time 6012ms: Process A6 completed a CPU burst; 16 bursts to go [Q A4 B4 B6 B7 A9 B1 A0 B2 A1 A7 B0 B3 A8 A2 A3 A5]
time 6012ms: Process A6 switching out of CPU; blocking on I/O until time 6029ms [Q A4 B4 B6 B7 A9 B1 A0 B2 A1 A7 B0 B3 A8 A2 A3 A5]
time 6015ms: Process A4 started using the CPU for 20ms burst [Q B4 B6 B7 A9 B1 A0 B2 A1 A7 B0 B3 A8 A2 A3 A5]
time 6029ms: Process A6 completed I/O; added to ready queue [Q B4 B6 B7 A9 B1 A0 B2 A1 A7 B0 B3 A8 A2 A3 A5 A6]
time 6035ms: Process A4 completed a CPU burst; 2 bursts to go [Q B4 B6 B7 A9 B1 A0 B2 A1 A7 B0 B3 A8 A2 A3 A5 A6]
time 6035ms: Process A4 switching out of CPU; blocking on I/O until time 6197ms [Q B4 B6 B7 A9 B1 A0 B2 A1 A7 B0 B3 A8 A2 A3 A5 A6]
time 6038ms: Process B4 started using the CPU for remaining 157ms of 285ms burst [Q B6 B7 A9 B1 A0 B2 A1 A7 B0 B3 A8 A2 A3 A5 A6]
time 6102ms: Time slice expired; preempting process B4 with 93ms remaining [Q B6 B7 A9 B1 A0 B2 A1 A7 B0 B3 A8 A2 A3 A5 A6]
time 6106ms: Process B6 started using the CPU for 142ms burst [Q B7 A9 B1 A0 B2 A1 A7 B0 B3 A8 A2 A3 A5 A6 B4]
time 6170ms: Time slice expired; preempting process B6 with 78ms remaining [Q B7 A9 B1 A0 B2 A1 A7 B0 B3 A8 A2 A3 A5 A6 B4]
time 6174ms: Process B7 started using the CPU for 3ms burst [Q A9 B1 A0 B2 A1 A7 B0 B3 A8 A2 A3 A5 A6 B4 B6]
time 6177ms: Process B7 completed a CPU burst; 23 bursts to go [Q A9 B1 A0 B2 A1 A7 B0 B3 A8 A2 A3 A5 A6 B4 B6]
time 6177ms: Process B7 switching out of CPU; blocking on I/O until time 9139ms [Q A9 B1 A0 B2 A1 A7 B0 B3 A8 A2 A3 A5 A6 B4 B6]
time 6180ms: Process A9 started using the CPU for 28ms burst [Q B1 A0 B2 A1 A7 B0 B3 A8 A2 A3 A5 A6 B4 B6]
time 6197ms: Process A4 completed I/O; added to ready queue [Q B1 A0 B2 A1 A7 B0 B3 A8 A2 A3 A5 A6 B4 B6 A4]
time 6208ms: Process A9 completed a CPU burst; 30 bursts to go [Q B1 A0 B2 A1 A7 B0 B3 A8 A2 A3 A5 A6 B4 B6 A4]
time 6208ms: Process A9 switching out of CPU; blocking on I/O until time 6238ms [Q B1 A0 B2 A1 A7 B0 B3 A8 A2 A3 A5 A6 B4 B6 A4]
time 6211ms: Process B1 started using the CPU for remaining 2684ms of 3004ms burst [Q A0 B2 A1 A7 B0 B3 A8 A2 A3 A5 A6 B4 B6 A4]
time 6238ms: Process A9 completed I/O; added to ready queue [Q A0 B2 A1 A7 B0 B3 A8 A2 A3 A5 A6 B4 B6 A4 A9]
time 6254ms: Process B9 completed I/O; added to ready queue [Q A0 B2 A1 A7 B0 B3 A8 A2 A3 A5 A6 B4 B6 A4 A9 B9]
time 6275ms: Time slice expired; preempting process B1 with 2620ms remaining [Q A0 B2 A1 A7 B0 B3 A8 A2 A3 A5 A6 B4 B6 A4 A9 B9]
time 6279ms: Process A0 started using the CPU for remaining 968ms of 1096ms burst [Q B2 A1 A7 B0 B3 A8 A2 A3 A5 A6 B4 B6 A4 A9 B9 B1]
time 6343ms: Time slice expired; preempting process A0 with 904ms remaining [Q B2 A1 A7 B0 B3 A8 A2 A3 A5 A6 B4 B6 A4 A9 B9 B1]
time 6347ms: Process B2 started using the CPU for 219ms burst [Q A1 A7 B0 B3 A8 A2 A3 A5 A6 B4 B6 A4 A9 B9 B1 A0]
time 6411ms: Time slice expired; preempting process B2 with 155ms remaining [Q A1 A7 B0 B3 A8 A2 A3 A5 A6 B4 B6 A4 A9 B9 B1 A0]
time 6415ms: Process A1 started using the CPU for remaining 248ms of 632ms burst [Q A7 B0 B3 A8 A2 A3 A5 A6 B4 B6 A4 A9 B9 B1 A0 B2]
time 6479ms: Time slice expired; preempting process A1 with 184ms remaining [Q A7 B0 B3 A8 A2 A3 A5 A6 B4 B6 A4 A9 B9 B1 A0 B2]
